Workbook

Sheet Read me
A1: 11DP-C · Live Gantt chart and Project Status
A2: Generated on 8 October 2026 from the plan submitted on 9 October (baseline). From then on, update it by hand.
A4: What to edit
A5: Only the yellow cells. Each owner updates their own rows: Real start, Real end, Status, Notes (Tasks); Real date and Status (Milestones);
A6: Likelihood, Impact, Status, Last review, Notes (Risks). Planned dates are the 9 October baseline and must not be changed.
A7: Example: when Leo starts task 2.1 on Tue 13 Oct, he writes 13/10/2026 in Real start and sets Status to 'In progress';
A8: when he finishes, he writes the Real end and sets 'Completed'. Delay is computed automatically (negative = early).
A9: Status values (Formal Requirements, Project Status Document): Backlog, Pending, In progress, Completed, Incident, Canceled.
A11: How to read the chart (Tasks sheet)
A12: Bar fill = phase of the planned task: grey Phase 0 (completed), blue WP1, teal WP2, amber WP3, purple WP4.
A13: Line under the bar = owner: red Aarón, lime Bruno, black Ettore, magenta Leo, azure Pol, grey all members.
A14: ● = real execution, drawn from Real start to Real end (or to today while the task is open). Red header cell = today. Shaded columns = holidays.
... A24: Yellow = cell to edit

Sheet Tasks
A1: 11DP-C · Pyruvate Kinase Deficiency: from a PKLR variant to haemolytic anaemia · live Gantt chart and Project Status
A2: Planned dates = baseline of 9 October 2026 (do not edit). Yellow cells are updated by each task owner: real start, real end, status, notes. Bar fill = phase (planned); line under the bar = owner; ● = real execution.
N3: 46279 | P3: 46286 | U3: 46293 | Z3: 46300 | AE3: 46307 | AJ3: 46314 | AO3: 46321 | AT3: 46328
A4: ID | B4: Phase | C4: Task | D4: Owner | E4: Duration (working days) | F4: Effort (days) | G4: Predecessors | H4: Planned start | I4: Planned end | J4: Real start | K4: Real end | L4: Status | M4: Delay (working days) | N4: 46282 | O4: 46283 | P4: 46286 | Q4: 46287 | R4: 46288 | S4: 46289 | T4: 46290 | U4: 46293 | V4: 46294 | W4: 46295 | X4: 46296 | Y4: 46297 | Z4: 46300 | AA4: 46301 | AB4: 46302 | AC4: 46303 | AD4: 46304 | AE4: 46307 | AF4: 46308 | AG4: 46309 | AH4: 46310 | AI4: 46311 | AJ4: 46314 | AK4: 46315 | AL4: 46316 | AM4: 46317 | AN4: 46318 | AO4: 46321 | AP4: 46322 | AQ4: 46323 | AR4: 46324 | AS4: 46325 | AT4: 46328 | AU4: 46329 | AV4: 46330 | AW4: 46331 | AX4: Notes (output, completion criterion, evidence, incidents)
A5: P0 | B5: P0 | C5: Phase 0 · Project start-up (completed) | E5: =NETWORKDAYS(H5,I5,Holidays!$A$2:$A$40) -> 15 | H5: =MIN(H6:H14) -> 46282 | I5: =MAX(I6:I14) -> 46303
A6: 0.1 | B6: P0 | C6: Create the GitHub repository and write the README | D6: Leo | E6: 1 | F6: 1 | H6: 46282 | I6: =WORKDAY(H6,E6-1,Holidays!$A$2:$A$40) -> 46282 | J6: 46282 | K6: 46282 | L6: Completed | M6: =IF(OR(K6="",I6=""),"",IF(K6>=I6,NETWORKDAYS(I6,K6,Holidays!$A$2:$A$40)-1,-(NETWORKDAYS(K6,I6,Holidays!$A$2:$A$40)-1))) -> 0 | N6: =IF(AND($J6<>"",N$4>=$J6,N$4<=IF($K6="",TODAY(),$K6),N$65=0),"●","") -> ● | O6: =IF(AND($J6<>"",O$4>=$J6,O$4<=IF($K6="",TODAY(),$K6),O$65=0),"●","") | P6: =IF(AND($J6<>"",P$4>=$J6,P$4<=IF($K6="",TODAY(),$K6),P$65=0),"●","") | Q6: =IF(AND($J6<>"",Q$4>=$J6,Q$4<=IF($K6="",TODAY(),$K6),Q$65=0),"●","") | R6: =IF(AND($J6<>"",R$4>=$J6,R$4<=IF($K6="",TODAY(),$K6),R$65=0),"●","") | S6: =IF(AND($J6<>"",S$4>=$J6,S$4<=IF($K6="",TODAY(),$K6),S$65=0),"●","") | T6: =IF(AND($J6<>"",T$4>=$J6,T$4<=IF($K6="",TODAY(),$K6),T$65=0),"●","") | U6: =IF(AND($J6<>"",U$4>=$J6,U$4<=IF($K6="",TODAY(),$K6),U$65=0),"●","") | ... AW6: =IF(AND($J6<>"",AW$4>=$J6,AW$4<=IF($K6="",TODAY(),$K6),AW$65=0),"●","") | AX6: Evidence: Commits of 17 Sep
A7: 0.2 | B7: P0 | C7: Create the report file and the folder structure | D7: Ettore | E7: 1 | F7: 1 | H7: 46282 | I7: =WORKDAY(H7,E7-1,Holidays!$A$2:$A$40) -> 46282 | J7: 46282 | K7: 46282 | L7: Completed | M7: =IF(OR(K7="",I7=""),"",IF(K7>=I7,NETWORKDAYS(I7,K7,Holidays!$A$2:$A$40)-1,-(NETWORKDAYS(K7,I7,Holidays!$A$2:$A$40)-1))) -> 0 | N7: =IF(AND($J7<>"",N$4>=$J7,N$4<=IF($K7="",TODAY(),$K7),N$65=0),"●","") -> ● | O7: =IF(AND($J7<>"",O$4>=$J7,O$4<=IF($K7="",TODAY(),$K7),O$65=0),"●","") | P7: =IF(AND($J7<>"",P$4>=$J7,P$4<=IF($K7="",TODAY(),$K7),P$65=0),"●","") | Q7: =IF(AND($J7<>"",Q$4>=$J7,Q$4<=IF($K7="",TODAY(),$K7),Q$65=0),"●","") | R7: =IF(AND($J7<>"",R$4>=$J7,R$4<=IF($K7="",TODAY(),$K7),R$65=0),"●","") | S7: =IF(AND($J7<>"",S$4>=$J7,S$4<=IF($K7="",TODAY(),$K7),S$65=0),"●","") | T7: =IF(AND($J7<>"",T$4>=$J7,T$4<=IF($K7="",TODAY(),$K7),T$65=0),"●","") | U7: =IF(AND($J7<>"",U$4>=$J7,U$4<=IF($K7="",TODAY(),$K7),U$65=0),"●","") | ... AW7: =IF(AND($J7<>"",AW$4>=$J7,AW$4<=IF($K7="",TODAY(),$K7),AW$65=0),"●","") | AX7: Evidence: Commits of 17 Sep
A8: 0.3 | B8: P0 | C8: Study the course instructions and the disease | D8: All | E8: 13 | F8: 13 | H8: 46286 | I8: =WORKDAY(H8,E8-1,Holidays!$A$2:$A$40) -> 46303 | J8: 46286 | K8: 46303 | L8: Completed | M8: =IF(OR(K8="",I8=""),"",IF(K8>=I8,NETWORKDAYS(I8,K8,Holidays!$A$2:$A$40)-1,-(NETWORKDAYS(K8,I8,Holidays!$A$2:$A$40)-1))) -> 0 | N8: =IF(AND($J8<>"",N$4>=$J8,N$4<=IF($K8="",TODAY(),$K8),N$65=0),"●","") | O8: =IF(AND($J8<>"",O$4>=$J8,O$4<=IF($K8="",TODAY(),$K8),O$65=0),"●","") | P8: =IF(AND($J8<>"",P$4>=$J8,P$4<=IF($K8="",TODAY(),$K8),P$65=0),"●","") -> ● | Q8: =IF(AND($J8<>"",Q$4>=$J8,Q$4<=IF($K8="",TODAY(),$K8),Q$65=0),"●","") -> ● | R8: =IF(AND($J8<>"",R$4>=$J8,R$4<=IF($K8="",TODAY(),$K8),R$65=0),"●","") -> ● | S8: =IF(AND($J8<>"",S$4>=$J8,S$4<=IF($K8="",TODAY(),$K8),S$65=0),"●","") | T8: =IF(AND($J8<>"",T$4>=$J8,T$4<=IF($K8="",TODAY(),$K8),T$65=0),"●","") -> ● | U8: =IF(AND($J8<>"",U$4>=$J8,U$4<=IF($K8="",TODAY(),$K8),U$65=0),"●","") -> ● | ... AW8: =IF(AND($J8<>"",AW$4>=$J8,AW$4<=IF($K8="",TODAY(),$K8),AW$65=0),"●","") | AX8: Evidence: Reported by the team
A9: 0.4 | B9: P0 | C9: Team meeting 1 (after class) | D9: All | E9: 1 | F9: 1 | H9: 46286 | I9: =WORKDAY(H9,E9-1,Holidays!$A$2:$A$40) -> 46286 | J9: 46286 | K9: 46286 | L9: Completed | M9: =IF(OR(K9="",I9=""),"",IF(K9>=I9,NETWORKDAYS(I9,K9,Holidays!$A$2:$A$40)-1,-(NETWORKDAYS(K9,I9,Holidays!$A$2:$A$40)-1))) -> 0 | N9: =IF(AND($J9<>"",N$4>=$J9,N$4<=IF($K9="",TODAY(),$K9),N$65=0),"●","") | O9: =IF(AND($J9<>"",O$4>=$J9,O$4<=IF($K9="",TODAY(),$K9),O$65=0),"●","") | P9: =IF(AND($J9<>"",P$4>=$J9,P$4<=IF($K9="",TODAY(),$K9),P$65=0),"●","") -> ● | Q9: =IF(AND($J9<>"",Q$4>=$J9,Q$4<=IF($K9="",TODAY(),$K9),Q$65=0),"●","") | R9: =IF(AND($J9<>"",R$4>=$J9,R$4<=IF($K9="",TODAY(),$K9),R$65=0),"●","") | S9: =IF(AND($J9<>"",S$4>=$J9,S$4<=IF($K9="",TODAY(),$K9),S$65=0),"●","") | T9: =IF(AND($J9<>"",T$4>=$J9,T$4<=IF($K9="",TODAY(),$K9),T$65=0),"●","") | U9: =IF(AND($J9<>"",U$4>=$J9,U$4<=IF($K9="",TODAY(),$K9),U$65=0),"●","") | ... AW9: =IF(AND($J9<>"",AW$4>=$J9,AW$4<=IF($K9="",TODAY(),$K9),AW$65=0),"●","") | AX9: Evidence: Reported by the team
A10: 0.5 | B10: P0 | C10: Format the report file | D10: Aarón | E10: 1 | F10: 1 | H10: 46293 | I10: =WORKDAY(H10,E10-1,Holidays!$A$2:$A$40) -> 46293 | J10: 46293 | K10: 46293 | L10: Completed | M10: =IF(OR(K10="",I10=""),"",IF(K10>=I10,NETWORKDAYS(I10,K10,Holidays!$A$2:$A$40)-1,-(NETWORKDAYS(K10,I10,Holidays!$A$2:$A$40)-1))) -> 0 | N10: =IF(AND($J10<>"",N$4>=$J10,N$4<=IF($K10="",TODAY(),$K10),N$65=0),"●","") | O10: =IF(AND($J10<>"",O$4>=$J10,O$4<=IF($K10="",TODAY(),$K10),O$65=0),"●","") | P10: =IF(AND($J10<>"",P$4>=$J10,P$4<=IF($K10="",TODAY(),$K10),P$65=0),"●","") | Q10: =IF(AND($J10<>"",Q$4>=$J10,Q$4<=IF($K10="",TODAY(),$K10),Q$65=0),"●","") | R10: =IF(AND($J10<>"",R$4>=$J10,R$4<=IF($K10="",TODAY(),$K10),R$65=0),"●","") | S10: =IF(AND($J10<>"",S$4>=$J10,S$4<=IF($K10="",TODAY(),$K10),S$65=0),"●","") | T10: =IF(AND($J10<>"",T$4>=$J10,T$4<=IF($K10="",TODAY(),$K10),T$65=0),"●","") | U10: =IF(AND($J10<>"",U$4>=$J10,U$4<=IF($K10="",TODAY(),$K10),U$65=0),"●","") -> ● | ... AW10: =IF(AND($J10<>"",AW$4>=$J10,AW$4<=IF($K10="",TODAY(),$K10),AW$65=0),"●","") | AX10: Evidence: Commit of 28 Sep
A11: 0.6 | B11: P0 | C11: Team meeting 2 (after class) | D11: All | E11: 1 | F11: 1 | H11: 46293 | I11: =WORKDAY(H11,E11-1,Holidays!$A$2:$A$40) -> 46293 | J11: 46293 | K11: 46293 | L11: Completed | M11: =IF(OR(K11="",I11=""),"",IF(K11>=I11,NETWORKDAYS(I11,K11,Holidays!$A$2:$A$40)-1,-(NETWORKDAYS(K11,I11,Holidays!$A$2:$A$40)-1))) -> 0 | N11: =IF(AND($J11<>"",N$4>=$J11,N$4<=IF($K11="",TODAY(),$K11),N$65=0),"●","") | O11: =IF(AND($J11<>"",O$4>=$J11,O$4<=IF($K11="",TODAY(),$K11),O$65=0),"●","") | P11: =IF(AND($J11<>"",P$4>=$J11,P$4<=IF($K11="",TODAY(),$K11),P$65=0),"●","") | Q11: =IF(AND($J11<>"",Q$4>=$J11,Q$4<=IF($K11="",TODAY(),$K11),Q$65=0),"●","") | R11: =IF(AND($J11<>"",R$4>=$J11,R$4<=IF($K11="",TODAY(),$K11),R$65=0),"●","") | S11: =IF(AND($J11<>"",S$4>=$J11,S$4<=IF($K11="",TODAY(),$K11),S$65=0),"●","") | T11: =IF(AND($J11<>"",T$4>=$J11,T$4<=IF($K11="",TODAY(),$K11),T$65=0),"●","") | U11: =IF(AND($J11<>"",U$4>=$J11,U$4<=IF($K11="",TODAY(),$K11),U$65=0),"●","") -> ● | ... AW11: =IF(AND($J11<>"",AW$4>=$J11,AW$4<=IF($K11="",TODAY(),$K11),AW$65=0),"●","") | AX11: Evidence: Reported by the team
A12: 0.7 | B12: P0 | C12: Team meeting 3 (after class) | D12: All | E12: 1 | F12: 1 | H12: 46300 | I12: =WORKDAY(H12,E12-1,Holidays!$A$2:$A$40) -> 46300 | J12: 46300 | K12: 46300 | L12: Completed | M12: =IF(OR(K12="",I12=""),"",IF(K12>=I12,NETWORKDAYS(I12,K12,Holidays!$A$2:$A$40)-1,-(NETWORKDAYS(K12,I12,Holidays!$A$2:$A$40)-1))) -> 0 | N12: =IF(AND($J12<>"",N$4>=$J12,N$4<=IF($K12="",TODAY(),$K12),N$65=0),"●","") | O12: =IF(AND($J12<>"",O$4>=$J12,O$4<=IF($K12="",TODAY(),$K12),O$65=0),"●","") | P12: =IF(AND($J12<>"",P$4>=$J12,P$4<=IF($K12="",TODAY(),$K12),P$65=0),"●","") | Q12: =IF(AND($J12<>"",Q$4>=$J12,Q$4<=IF($K12="",TODAY(),$K12),Q$65=0),"●","") | R12: =IF(AND($J12<>"",R$4>=$J12,R$4<=IF($K12="",TODAY(),$K12),R$65=0),"●","") | S12: =IF(AND($J12<>"",S$4>=$J12,S$4<=IF($K12="",TODAY(),$K12),S$65=0),"●","") | T12: =IF(AND($J12<>"",T$4>=$J12,T$4<=IF($K12="",TODAY(),$K12),T$65=0),"●","") | U12: =IF(AND($J12<>"",U$4>=$J12,U$4<=IF($K12="",TODAY(),$K12),U$65=0),"●","") | ... AW12: =IF(AND($J12<>"",AW$4>=$J12,AW$4<=IF($K12="",TODAY(),$K12),AW$65=0),"●","") | AX12: Evidence: Reported by the team
A13: 0.8 | B13: P0 | C13: Draft the project plan (introduction, objectives, Gantt chart, risks) | D13: Ettore | E13: 4 | F13: 4 | H13: 46300 | I13: =WORKDAY(H13,E13-1,Holidays!$A$2:$A$40) -> 46303 | J13: 46300 | K13: 46303 | L13: Completed | M13: =IF(OR(K13="",I13=""),"",IF(K13>=I13,NETWORKDAYS(I13,K13,Holidays!$A$2:$A$40)-1,-(NETWORKDAYS(K13,I13,Holidays!$A$2:$A$40)-1))) -> 0 | N13: =IF(AND($J13<>"",N$4>=$J13,N$4<=IF($K13="",TODAY(),$K13),N$65=0),"●","") | O13: =IF(AND($J13<>"",O$4>=$J13,O$4<=IF($K13="",TODAY(),$K13),O$65=0),"●","") | P13: =IF(AND($J13<>"",P$4>=$J13,P$4<=IF($K13="",TODAY(),$K13),P$65=0),"●","") | Q13: =IF(AND($J13<>"",Q$4>=$J13,Q$4<=IF($K13="",TODAY(),$K13),Q$65=0),"●","") | R13: =IF(AND($J13<>"",R$4>=$J13,R$4<=IF($K13="",TODAY(),$K13),R$65=0),"●","") | S13: =IF(AND($J13<>"",S$4>=$J13,S$4<=IF($K13="",TODAY(),$K13),S$65=0),"●","") | T13: =IF(AND($J13<>"",T$4>=$J13,T$4<=IF($K13="",TODAY(),$K13),T$65=0),"●","") | U13: =IF(AND($J13<>"",U$4>=$J13,U$4<=IF($K13="",TODAY(),$K13),U$65=0),"●","") | ... AW13: =IF(AND($J13<>"",AW$4>=$J13,AW$4<=IF($K13="",TODAY(),$K13),AW$65=0),"●","") | AX13: Evidence: Draft files
A14: 0.9 | B14: P0 | C14: Team meeting 4 (after class): review of the draft plan; decision to submit it through GitHub rather than as a PDF | D14: All | E14: 1 | F14: 1 | H14: 46303 | I14: =WORKDAY(H14,E14-1,Holidays!$A$2:$A$40) -> 46303 | J14: 46303 | K14: 46303 | L14: Completed | M14: =IF(OR(K14="",I14=""),"",IF(K14>=I14,NETWORKDAYS(I14,K14,Holidays!$A$2:$A$40)-1,-(NETWORKDAYS(K14,I14,Holidays!$A$2:$A$40)-1))) -> 0 | N14: =IF(AND($J14<>"",N$4>=$J14,N$4<=IF($K14="",TODAY(),$K14),N$65=0),"●","") | O14: =IF(AND($J14<>"",O$4>=$J14,O$4<=IF($K14="",TODAY(),$K14),O$65=0),"●","") | P14: =IF(AND($J14<>"",P$4>=$J14,P$4<=IF($K14="",TODAY(),$K14),P$65=0),"●","") | Q14: =IF(AND($J14<>"",Q$4>=$J14,Q$4<=IF($K14="",TODAY(),$K14),Q$65=0),"●","") | R14: =IF(AND($J14<>"",R$4>=$J14,R$4<=IF($K14="",TODAY(),$K14),R$65=0),"●","") | S14: =IF(AND($J14<>"",S$4>=$J14,S$4<=IF($K14="",TODAY(),$K14),S$65=0),"●","") | T14: =IF(AND($J14<>"",T$4>=$J14,T$4<=IF($K14="",TODAY(),$K14),T$65=0),"●","") | U14: =IF(AND($J14<>"",U$4>=$J14,U$4<=IF($K14="",TODAY(),$K14),U$65=0),"●","") | ... AW14: =IF(AND($J14<>"",AW$4>=$J14,AW$4<=IF($K14="",TODAY(),$K14),AW$65=0),"●","") | AX14: Evidence: Reported by the team
A15: WP1 | B15: WP1 | C15: WP1 · Project management and GitHub | E15: =NETWORKDAYS(H15,I15,Holidays!$A$2:$A$40) -> 12 | H15: =MIN(H16:H24) -> 46304 | I15: =MAX(I16:I24) -> 46322
A16: 1.1 | B16: WP1 | C16: Review and commit the introduction (PKD_1); create the folders report/, status/, gantt/, and references/ | D16: Ettore | E16: 1 | F16: 1 | H16: 46304 | I16: =WORKDAY(H16,E16-1,Holidays!$A$2:$A$40) -> 46304 | L16: Pending | M16: =IF(OR(K16="",I16=""),"",IF(K16>=I16,NETWORKDAYS(I16,K16,Holidays!$A$2:$A$40)-1,-(NETWORKDAYS(K16,I16,Holidays!$A$2:$A$40)-1))) | N16: =IF(AND($J16<>"",N$4>=$J16,N$4<=IF($K16="",TODAY(),$K16),N$65=0),"●","") | O16: =IF(AND($J16<>"",O$4>=$J16,O$4<=IF($K16="",TODAY(),$K16),O$65=0),"●","") | P16: =IF(AND($J16<>"",P$4>=$J16,P$4<=IF($K16="",TODAY(),$K16),P$65=0),"●","") | Q16: =IF(AND($J16<>"",Q$4>=$J16,Q$4<=IF($K16="",TODAY(),$K16),Q$65=0),"●","") | R16: =IF(AND($J16<>"",R$4>=$J16,R$4<=IF($K16="",TODAY(),$K16),R$65=0),"●","") | S16: =IF(AND($J16<>"",S$4>=$J16,S$4<=IF($K16="",TODAY(),$K16),S$65=0),"●","") | T16: =IF(AND($J16<>"",T$4>=$J16,T$4<=IF($K16="",TODAY(),$K16),T$65=0),"●","") | U16: =IF(AND($J16<>"",U$4>=$J16,U$4<=IF($K16="",TODAY(),$K16),U$65=0),"●","") | ... AW16: =IF(AND($J16<>"",AW$4>=$J16,AW$4<=IF($K16="",TODAY(),$K16),AW$65=0),"●","") | AX16: Output: Introduction and required folders in the repository. Accomplished when: The four required folders exist and the introduction is committed by its reviewer.
A17: 1.2 | B17: WP1 | C17: Review and commit the overview and team section (PKD_2); submit the repository URL on Moodle | D17: Aarón | E17: 1 | F17: 1 | G17: 1.1 | H17: 46304 | I17: =WORKDAY(H17,E17-1,Holidays!$A$2:$A$40) -> 46304 | L17: Pending | M17: =IF(OR(K17="",I17=""),"",IF(K17>=I17,NETWORKDAYS(I17,K17,Holidays!$A$2:$A$40)-1,-(NETWORKDAYS(K17,I17,Holidays!$A$2:$A$40)-1))) | N17: =IF(AND($J17<>"",N$4>=$J17,N$4<=IF($K17="",TODAY(),$K17),N$65=0),"●","") | O17: =IF(AND($J17<>"",O$4>=$J17,O$4<=IF($K17="",TODAY(),$K17),O$65=0),"●","") | P17: =IF(AND($J17<>"",P$4>=$J17,P$4<=IF($K17="",TODAY(),$K17),P$65=0),"●","") | Q17: =IF(AND($J17<>"",Q$4>=$J17,Q$4<=IF($K17="",TODAY(),$K17),Q$65=0),"●","") | R17: =IF(AND($J17<>"",R$4>=$J17,R$4<=IF($K17="",TODAY(),$K17),R$65=0),"●","") | S17: =IF(AND($J17<>"",S$4>=$J17,S$4<=IF($K17="",TODAY(),$K17),S$65=0),"●","") | T17: =IF(AND($J17<>"",T$4>=$J17,T$4<=IF($K17="",TODAY(),$K17),T$65=0),"●","") | U17: =IF(AND($J17<>"",U$4>=$J17,U$4<=IF($K17="",TODAY(),$K17),U$65=0),"●","") | ... AW17: =IF(AND($J17<>"",AW$4>=$J17,AW$4<=IF($K17="",TODAY(),$K17),AW$65=0),"●","") | AX17: Output: PKD_2 committed; URL submitted. Accomplished when: The URL is submitted on Moodle before 18:00 on 9 Oct.
A18: 1.3 | B18: WP1 | C18: Review and commit the Gantt chart (PKD_3) | D18: Leo | E18: 1 | F18: 1 | G18: 1.1 | H18: 46304 | I18: =WORKDAY(H18,E18-1,Holidays!$A$2:$A$40) -> 46304 | L18: Pending | M18: =IF(OR(K18="",I18=""),"",IF(K18>=I18,NETWORKDAYS(I18,K18,Holidays!$A$2:$A$40)-1,-(NETWORKDAYS(K18,I18,Holidays!$A$2:$A$40)-1))) | N18: =IF(AND($J18<>"",N$4>=$J18,N$4<=IF($K18="",TODAY(),$K18),N$65=0),"●","") | O18: =IF(AND($J18<>"",O$4>=$J18,O$4<=IF($K18="",TODAY(),$K18),O$65=0),"●","") | P18: =IF(AND($J18<>"",P$4>=$J18,P$4<=IF($K18="",TODAY(),$K18),P$65=0),"●","") | Q18: =IF(AND($J18<>"",Q$4>=$J18,Q$4<=IF($K18="",TODAY(),$K18),Q$65=0),"●","") | R18: =IF(AND($J18<>"",R$4>=$J18,R$4<=IF($K18="",TODAY(),$K18),R$65=0),"●","") | S18: =IF(AND($J18<>"",S$4>=$J18,S$4<=IF($K18="",TODAY(),$K18),S$65=0),"●","") | T18: =IF(AND($J18<>"",T$4>=$J18,T$4<=IF($K18="",TODAY(),$K18),T$65=0),"●","") | U18: =IF(AND($J18<>"",U$4>=$J18,U$4<=IF($K18="",TODAY(),$K18),U$65=0),"●","") | ... AW18: =IF(AND($J18<>"",AW$4>=$J18,AW$4<=IF($K18="",TODAY(),$K18),AW$65=0),"●","") | AX18: Output: PKD_3 committed. Accomplished when: The chart renders on GitHub and its dates match PKD_4.
A19: 1.4 | B19: WP1 | C19: Review and commit the task details (PKD_4) | D19: Pol | E19: 1 | F19: 1 | G19: 1.1 | H19: 46304 | I19: =WORKDAY(H19,E19-1,Holidays!$A$2:$A$40) -> 46304 | L19: Pending | M19: =IF(OR(K19="",I19=""),"",IF(K19>=I19,NETWORKDAYS(I19,K19,Holidays!$A$2:$A$40)-1,-(NETWORKDAYS(K19,I19,Holidays!$A$2:$A$40)-1))) | N19: =IF(AND($J19<>"",N$4>=$J19,N$4<=IF($K19="",TODAY(),$K19),N$65=0),"●","") | O19: =IF(AND($J19<>"",O$4>=$J19,O$4<=IF($K19="",TODAY(),$K19),O$65=0),"●","") | P19: =IF(AND($J19<>"",P$4>=$J19,P$4<=IF($K19="",TODAY(),$K19),P$65=0),"●","") | Q19: =IF(AND($J19<>"",Q$4>=$J19,Q$4<=IF($K19="",TODAY(),$K19),Q$65=0),"●","") | R19: =IF(AND($J19<>"",R$4>=$J19,R$4<=IF($K19="",TODAY(),$K19),R$65=0),"●","") | S19: =IF(AND($J19<>"",S$4>=$J19,S$4<=IF($K19="",TODAY(),$K19),S$65=0),"●","") | T19: =IF(AND($J19<>"",T$4>=$J19,T$4<=IF($K19="",TODAY(),$K19),T$65=0),"●","") | U19: =IF(AND($J19<>"",U$4>=$J19,U$4<=IF($K19="",TODAY(),$K19),U$65=0),"●","") | ... AW19: =IF(AND($J19<>"",AW$4>=$J19,AW$4<=IF($K19="",TODAY(),$K19),AW$65=0),"●","") | AX19: Output: PKD_4 committed. Accomplished when: Every task has an owner, output, duration, predecessor, and completion criterion.
A20: 1.5 | B20: WP1 | C20: Review and commit the risk analysis and references (PKD_5, PKD_6) | D20: Bruno | E20: 1 | F20: 1 | G20: 1.1 | H20: 46304 | I20: =WORKDAY(H20,E20-1,Holidays!$A$2:$A$40) -> 46304 | L20: Pending | M20: =IF(OR(K20="",I20=""),"",IF(K20>=I20,NETWORKDAYS(I20,K20,Holidays!$A$2:$A$40)-1,-(NETWORKDAYS(K20,I20,Holidays!$A$2:$A$40)-1))) | N20: =IF(AND($J20<>"",N$4>=$J20,N$4<=IF($K20="",TODAY(),$K20),N$65=0),"●","") | O20: =IF(AND($J20<>"",O$4>=$J20,O$4<=IF($K20="",TODAY(),$K20),O$65=0),"●","") | P20: =IF(AND($J20<>"",P$4>=$J20,P$4<=IF($K20="",TODAY(),$K20),P$65=0),"●","") | Q20: =IF(AND($J20<>"",Q$4>=$J20,Q$4<=IF($K20="",TODAY(),$K20),Q$65=0),"●","") | R20: =IF(AND($J20<>"",R$4>=$J20,R$4<=IF($K20="",TODAY(),$K20),R$65=0),"●","") | S20: =IF(AND($J20<>"",S$4>=$J20,S$4<=IF($K20="",TODAY(),$K20),S$65=0),"●","") | T20: =IF(AND($J20<>"",T$4>=$J20,T$4<=IF($K20="",TODAY(),$K20),T$65=0),"●","") | U20: =IF(AND($J20<>"",U$4>=$J20,U$4<=IF($K20="",TODAY(),$K20),U$65=0),"●","") | ... AW20: =IF(AND($J20<>"",AW$4>=$J20,AW$4<=IF($K20="",TODAY(),$K20),AW$65=0),"●","") | AX20: Output: PKD_5 and PKD_6 committed. Accomplished when: Each risk has a score and a contingency plan; every citation has a reference.
A21: 1.6 | B21: WP1 | C21: Create the Project Status document | D21: Ettore | E21: 1 | F21: 1 | G21: 1.2 | H21: 46308 | I21: =WORKDAY(H21,E21-1,Holidays!$A$2:$A$40) -> 46308 | L21: Pending | M21: =IF(OR(K21="",I21=""),"",IF(K21>=I21,NETWORKDAYS(I21,K21,Holidays!$A$2:$A$40)-1,-(NETWORKDAYS(K21,I21,Holidays!$A$2:$A$40)-1))) | N21: =IF(AND($J21<>"",N$4>=$J21,N$4<=IF($K21="",TODAY(),$K21),N$65=0),"●","") | O21: =IF(AND($J21<>"",O$4>=$J21,O$4<=IF($K21="",TODAY(),$K21),O$65=0),"●","") | P21: =IF(AND($J21<>"",P$4>=$J21,P$4<=IF($K21="",TODAY(),$K21),P$65=0),"●","") | Q21: =IF(AND($J21<>"",Q$4>=$J21,Q$4<=IF($K21="",TODAY(),$K21),Q$65=0),"●","") | R21: =IF(AND($J21<>"",R$4>=$J21,R$4<=IF($K21="",TODAY(),$K21),R$65=0),"●","") | S21: =IF(AND($J21<>"",S$4>=$J21,S$4<=IF($K21="",TODAY(),$K21),S$65=0),"●","") | T21: =IF(AND($J21<>"",T$4>=$J21,T$4<=IF($K21="",TODAY(),$K21),T$65=0),"●","") | U21: =IF(AND($J21<>"",U$4>=$J21,U$4<=IF($K21="",TODAY(),$K21),U$65=0),"●","") | ... AW21: =IF(AND($J21<>"",AW$4>=$J21,AW$4<=IF($K21="",TODAY(),$K21),AW$65=0),"●","") | AX21: Output: `status/` document. Accomplished when: It lists every task with owner, planned dates, real dates, status, and notes.
A22: 1.7 | B22: WP1 | C22: Weekly status update and team meeting (Fridays 16 and 23 Oct) | D22: Ettore | E22: 6 | F22: 2 | G22: 1.6 | H22: 46311 | I22: =WORKDAY(H22,E22-1,Holidays!$A$2:$A$40) -> 46318 | L22: Pending | M22: =IF(OR(K22="",I22=""),"",IF(K22>=I22,NETWORKDAYS(I22,K22,Holidays!$A$2:$A$40)-1,-(NETWORKDAYS(K22,I22,Holidays!$A$2:$A$40)-1))) | N22: =IF(AND($J22<>"",N$4>=$J22,N$4<=IF($K22="",TODAY(),$K22),N$65=0),"●","") | O22: =IF(AND($J22<>"",O$4>=$J22,O$4<=IF($K22="",TODAY(),$K22),O$65=0),"●","") | P22: =IF(AND($J22<>"",P$4>=$J22,P$4<=IF($K22="",TODAY(),$K22),P$65=0),"●","") | Q22: =IF(AND($J22<>"",Q$4>=$J22,Q$4<=IF($K22="",TODAY(),$K22),Q$65=0),"●","") | R22: =IF(AND($J22<>"",R$4>=$J22,R$4<=IF($K22="",TODAY(),$K22),R$65=0),"●","") | S22: =IF(AND($J22<>"",S$4>=$J22,S$4<=IF($K22="",TODAY(),$K22),S$65=0),"●","") | T22: =IF(AND($J22<>"",T$4>=$J22,T$4<=IF($K22="",TODAY(),$K22),T$65=0),"●","") | U22: =IF(AND($J22<>"",U$4>=$J22,U$4<=IF($K22="",TODAY(),$K22),U$65=0),"●","") | ... AW22: =IF(AND($J22<>"",AW$4>=$J22,AW$4<=IF($K22="",TODAY(),$K22),AW$65=0),"●","") | AX22: Output: Dated notes in `status/`. Accomplished when: After each meeting, real dates, status changes, and incidents are recorded.
A23: 1.8 | B23: WP1 | C23: Prepare the Project Status document for the 22 Oct discussion | D23: Ettore | E23: 1 | F23: 1 | G23: 1.6 | H23: 46315 | I23: =WORKDAY(H23,E23-1,Holidays!$A$2:$A$40) -> 46315 | L23: Pending | M23: =IF(OR(K23="",I23=""),"",IF(K23>=I23,NETWORKDAYS(I23,K23,Holidays!$A$2:$A$40)-1,-(NETWORKDAYS(K23,I23,Holidays!$A$2:$A$40)-1))) | N23: =IF(AND($J23<>"",N$4>=$J23,N$4<=IF($K23="",TODAY(),$K23),N$65=0),"●","") | O23: =IF(AND($J23<>"",O$4>=$J23,O$4<=IF($K23="",TODAY(),$K23),O$65=0),"●","") | P23: =IF(AND($J23<>"",P$4>=$J23,P$4<=IF($K23="",TODAY(),$K23),P$65=0),"●","") | Q23: =IF(AND($J23<>"",Q$4>=$J23,Q$4<=IF($K23="",TODAY(),$K23),Q$65=0),"●","") | R23: =IF(AND($J23<>"",R$4>=$J23,R$4<=IF($K23="",TODAY(),$K23),R$65=0),"●","") | S23: =IF(AND($J23<>"",S$4>=$J23,S$4<=IF($K23="",TODAY(),$K23),S$65=0),"●","") | T23: =IF(AND($J23<>"",T$4>=$J23,T$4<=IF($K23="",TODAY(),$K23),T$65=0),"●","") | U23: =IF(AND($J23<>"",U$4>=$J23,U$4<=IF($K23="",TODAY(),$K23),U$65=0),"●","") | ... AW23: =IF(AND($J23<>"",AW$4>=$J23,AW$4<=IF($K23="",TODAY(),$K23),AW$65=0),"●","") | AX23: Output: Updated `status/` document. Accomplished when: Planned and real dates, status, and notes are current on 20 Oct.
A24: 1.9 | B24: WP1 | C24: Produce the final Gantt chart with real dates (live version) | D24: Ettore | E24: 1 | F24: 1 | G24: 4.6 | H24: 46322 | I24: =WORKDAY(H24,E24-1,Holidays!$A$2:$A$40) -> 46322 | L24: Pending | M24: =IF(OR(K24="",I24=""),"",IF(K24>=I24,NETWORKDAYS(I24,K24,Holidays!$A$2:$A$40)-1,-(NETWORKDAYS(K24,I24,Holidays!$A$2:$A$40)-1))) | N24: =IF(AND($J24<>"",N$4>=$J24,N$4<=IF($K24="",TODAY(),$K24),N$65=0),"●","") | O24: =IF(AND($J24<>"",O$4>=$J24,O$4<=IF($K24="",TODAY(),$K24),O$65=0),"●","") | P24: =IF(AND($J24<>"",P$4>=$J24,P$4<=IF($K24="",TODAY(),$K24),P$65=0),"●","") | Q24: =IF(AND($J24<>"",Q$4>=$J24,Q$4<=IF($K24="",TODAY(),$K24),Q$65=0),"●","") | R24: =IF(AND($J24<>"",R$4>=$J24,R$4<=IF($K24="",TODAY(),$K24),R$65=0),"●","") | S24: =IF(AND($J24<>"",S$4>=$J24,S$4<=IF($K24="",TODAY(),$K24),S$65=0),"●","") | T24: =IF(AND($J24<>"",T$4>=$J24,T$4<=IF($K24="",TODAY(),$K24),T$65=0),"●","") | U24: =IF(AND($J24<>"",U$4>=$J24,U$4<=IF($K24="",TODAY(),$K24),U$65=0),"●","") | ... AW24: =IF(AND($J24<>"",AW$4>=$J24,AW$4<=IF($K24="",TODAY(),$K24),AW$65=0),"●","") | AX24: Output: Final Gantt chart in `gantt/`. Accomplished when: Every task shows its real dates, and deviations are explained.
A25: WP2 | B25: WP2 | C25: WP2 · Data sources, literature, and sequences | E25: =NETWORKDAYS(H25,I25,Holidays!$A$2:$A$40) -> 5 | H25: =MIN(H26:H33) -> 46308 | I25: =MAX(I26:I33) -> 46314
A26: 2.1 | B26: WP2 | C26: Characterize the supplied sequences: translate both CDSs, compare wild type and mutant, and name the variant in HGVS nomenclature | D26: Leo | E26: 1 | F26: 1 | G26: 1.3 | H26: 46308 | I26: =WORKDAY(H26,E26-1,Holidays!$A$2:$A$40) -> 46308 | L26: Pending | M26: =IF(OR(K26="",I26=""),"",IF(K26>=I26,NETWORKDAYS(I26,K26,Holidays!$A$2:$A$40)-1,-(NETWORKDAYS(K26,I26,Holidays!$A$2:$A$40)-1))) | N26: =IF(AND($J26<>"",N$4>=$J26,N$4<=IF($K26="",TODAY(),$K26),N$65=0),"●","") | O26: =IF(AND($J26<>"",O$4>=$J26,O$4<=IF($K26="",TODAY(),$K26),O$65=0),"●","") | P26: =IF(AND($J26<>"",P$4>=$J26,P$4<=IF($K26="",TODAY(),$K26),P$65=0),"●","") | Q26: =IF(AND($J26<>"",Q$4>=$J26,Q$4<=IF($K26="",TODAY(),$K26),Q$65=0),"●","") | R26: =IF(AND($J26<>"",R$4>=$J26,R$4<=IF($K26="",TODAY(),$K26),R$65=0),"●","") | S26: =IF(AND($J26<>"",S$4>=$J26,S$4<=IF($K26="",TODAY(),$K26),S$65=0),"●","") | T26: =IF(AND($J26<>"",T$4>=$J26,T$4<=IF($K26="",TODAY(),$K26),T$65=0),"●","") | U26: =IF(AND($J26<>"",U$4>=$J26,U$4<=IF($K26="",TODAY(),$K26),U$65=0),"●","") | ... AW26: =IF(AND($J26<>"",AW$4>=$J26,AW$4<=IF($K26="",TODAY(),$K26),AW$65=0),"●","") | AX26: Output: Variant table (DNA and protein level). Accomplished when: Every difference is listed at DNA and protein level and verified by a second member (task 2.8).
A27: 2.2 | B27: WP2 | C27: Identify the gene, the isoform, and the reference entries (HGNC, NCBI Gene, UniProt) | D27: Bruno | E27: 1 | F27: 1 | G27: 1.5 | H27: 46308 | I27: =WORKDAY(H27,E27-1,Holidays!$A$2:$A$40) -> 46308 | L27: Pending | M27: =IF(OR(K27="",I27=""),"",IF(K27>=I27,NETWORKDAYS(I27,K27,Holidays!$A$2:$A$40)-1,-(NETWORKDAYS(K27,I27,Holidays!$A$2:$A$40)-1))) | N27: =IF(AND($J27<>"",N$4>=$J27,N$4<=IF($K27="",TODAY(),$K27),N$65=0),"●","") | O27: =IF(AND($J27<>"",O$4>=$J27,O$4<=IF($K27="",TODAY(),$K27),O$65=0),"●","") | P27: =IF(AND($J27<>"",P$4>=$J27,P$4<=IF($K27="",TODAY(),$K27),P$65=0),"●","") | Q27: =IF(AND($J27<>"",Q$4>=$J27,Q$4<=IF($K27="",TODAY(),$K27),Q$65=0),"●","") | R27: =IF(AND($J27<>"",R$4>=$J27,R$4<=IF($K27="",TODAY(),$K27),R$65=0),"●","") | S27: =IF(AND($J27<>"",S$4>=$J27,S$4<=IF($K27="",TODAY(),$K27),S$65=0),"●","") | T27: =IF(AND($J27<>"",T$4>=$J27,T$4<=IF($K27="",TODAY(),$K27),T$65=0),"●","") | U27: =IF(AND($J27<>"",U$4>=$J27,U$4<=IF($K27="",TODAY(),$K27),U$65=0),"●","") | ... AW27: =IF(AND($J27<>"",AW$4>=$J27,AW$4<=IF($K27="",TODAY(),$K27),AW$65=0),"●","") | AX27: Output: Table of identifiers. Accomplished when: The gene symbol, isoform, and accession numbers are recorded with access dates.
A28: 2.3 | B28: WP2 | C28: Collect clinical and population evidence on the variant (ClinVar, gnomAD, OMIM, literature) | D28: Bruno | E28: 2 | F28: 2 | G28: 2.1, 2.5 | H28: 46310 | I28: =WORKDAY(H28,E28-1,Holidays!$A$2:$A$40) -> 46311 | L28: Pending | M28: =IF(OR(K28="",I28=""),"",IF(K28>=I28,NETWORKDAYS(I28,K28,Holidays!$A$2:$A$40)-1,-(NETWORKDAYS(K28,I28,Holidays!$A$2:$A$40)-1))) | N28: =IF(AND($J28<>"",N$4>=$J28,N$4<=IF($K28="",TODAY(),$K28),N$65=0),"●","") | O28: =IF(AND($J28<>"",O$4>=$J28,O$4<=IF($K28="",TODAY(),$K28),O$65=0),"●","") | P28: =IF(AND($J28<>"",P$4>=$J28,P$4<=IF($K28="",TODAY(),$K28),P$65=0),"●","") | Q28: =IF(AND($J28<>"",Q$4>=$J28,Q$4<=IF($K28="",TODAY(),$K28),Q$65=0),"●","") | R28: =IF(AND($J28<>"",R$4>=$J28,R$4<=IF($K28="",TODAY(),$K28),R$65=0),"●","") | S28: =IF(AND($J28<>"",S$4>=$J28,S$4<=IF($K28="",TODAY(),$K28),S$65=0),"●","") | T28: =IF(AND($J28<>"",T$4>=$J28,T$4<=IF($K28="",TODAY(),$K28),T$65=0),"●","") | U28: =IF(AND($J28<>"",U$4>=$J28,U$4<=IF($K28="",TODAY(),$K28),U$65=0),"●","") | ... AW28: =IF(AND($J28<>"",AW$4>=$J28,AW$4<=IF($K28="",TODAY(),$K28),AW$65=0),"●","") | AX28: Output: Evidence table with sources. Accomplished when: Classification, allele frequency, and published functional data are recorded with sources.
A29: 2.4 | B29: WP2 | C29: Review the literature on PK and PKD: normal function, mechanism, inheritance, and clinical features | D29: Aarón | E29: 3 | F29: 3 | G29: 1.2 | H29: 46308 | I29: =WORKDAY(H29,E29-1,Holidays!$A$2:$A$40) -> 46310 | L29: Pending | M29: =IF(OR(K29="",I29=""),"",IF(K29>=I29,NETWORKDAYS(I29,K29,Holidays!$A$2:$A$40)-1,-(NETWORKDAYS(K29,I29,Holidays!$A$2:$A$40)-1))) | N29: =IF(AND($J29<>"",N$4>=$J29,N$4<=IF($K29="",TODAY(),$K29),N$65=0),"●","") | O29: =IF(AND($J29<>"",O$4>=$J29,O$4<=IF($K29="",TODAY(),$K29),O$65=0),"●","") | P29: =IF(AND($J29<>"",P$4>=$J29,P$4<=IF($K29="",TODAY(),$K29),P$65=0),"●","") | Q29: =IF(AND($J29<>"",Q$4>=$J29,Q$4<=IF($K29="",TODAY(),$K29),Q$65=0),"●","") | R29: =IF(AND($J29<>"",R$4>=$J29,R$4<=IF($K29="",TODAY(),$K29),R$65=0),"●","") | S29: =IF(AND($J29<>"",S$4>=$J29,S$4<=IF($K29="",TODAY(),$K29),S$65=0),"●","") | T29: =IF(AND($J29<>"",T$4>=$J29,T$4<=IF($K29="",TODAY(),$K29),T$65=0),"●","") | U29: =IF(AND($J29<>"",U$4>=$J29,U$4<=IF($K29="",TODAY(),$K29),U$65=0),"●","") | ... AW29: =IF(AND($J29<>"",AW$4>=$J29,AW$4<=IF($K29="",TODAY(),$K29),AW$65=0),"●","") | AX29: Output: Annotated literature notes. Accomplished when: Each statement planned for the Background has at least one primary or review source.
A30: 2.5 | B30: WP2 | C30: Retrieve the reviewed orthologous sequences: rat, mouse, and dog (outgroup) | D30: Bruno | E30: 1 | F30: 1 | G30: 2.2 | H30: 46309 | I30: =WORKDAY(H30,E30-1,Holidays!$A$2:$A$40) -> 46309 | L30: Pending | M30: =IF(OR(K30="",I30=""),"",IF(K30>=I30,NETWORKDAYS(I30,K30,Holidays!$A$2:$A$40)-1,-(NETWORKDAYS(K30,I30,Holidays!$A$2:$A$40)-1))) | N30: =IF(AND($J30<>"",N$4>=$J30,N$4<=IF($K30="",TODAY(),$K30),N$65=0),"●","") | O30: =IF(AND($J30<>"",O$4>=$J30,O$4<=IF($K30="",TODAY(),$K30),O$65=0),"●","") | P30: =IF(AND($J30<>"",P$4>=$J30,P$4<=IF($K30="",TODAY(),$K30),P$65=0),"●","") | Q30: =IF(AND($J30<>"",Q$4>=$J30,Q$4<=IF($K30="",TODAY(),$K30),Q$65=0),"●","") | R30: =IF(AND($J30<>"",R$4>=$J30,R$4<=IF($K30="",TODAY(),$K30),R$65=0),"●","") | S30: =IF(AND($J30<>"",S$4>=$J30,S$4<=IF($K30="",TODAY(),$K30),S$65=0),"●","") | T30: =IF(AND($J30<>"",T$4>=$J30,T$4<=IF($K30="",TODAY(),$K30),T$65=0),"●","") | U30: =IF(AND($J30<>"",U$4>=$J30,U$4<=IF($K30="",TODAY(),$K30),U$65=0),"●","") | ... AW30: =IF(AND($J30<>"",AW$4>=$J30,AW$4<=IF($K30="",TODAY(),$K30),AW$65=0),"●","") | AX30: Output: FASTA files and accession list. Accomplished when: Every sequence is saved in the repository with its accession number.
A31: 2.6 | B31: WP2 | C31: Select the experimental structures: wild-type and mutant human R-type PK; rat PK | D31: Pol | E31: 1 | F31: 1 | G31: 1.4 | H31: 46308 | I31: =WORKDAY(H31,E31-1,Holidays!$A$2:$A$40) -> 46308 | L31: Pending | M31: =IF(OR(K31="",I31=""),"",IF(K31>=I31,NETWORKDAYS(I31,K31,Holidays!$A$2:$A$40)-1,-(NETWORKDAYS(K31,I31,Holidays!$A$2:$A$40)-1))) | N31: =IF(AND($J31<>"",N$4>=$J31,N$4<=IF($K31="",TODAY(),$K31),N$65=0),"●","") | O31: =IF(AND($J31<>"",O$4>=$J31,O$4<=IF($K31="",TODAY(),$K31),O$65=0),"●","") | P31: =IF(AND($J31<>"",P$4>=$J31,P$4<=IF($K31="",TODAY(),$K31),P$65=0),"●","") | Q31: =IF(AND($J31<>"",Q$4>=$J31,Q$4<=IF($K31="",TODAY(),$K31),Q$65=0),"●","") | R31: =IF(AND($J31<>"",R$4>=$J31,R$4<=IF($K31="",TODAY(),$K31),R$65=0),"●","") | S31: =IF(AND($J31<>"",S$4>=$J31,S$4<=IF($K31="",TODAY(),$K31),S$65=0),"●","") | T31: =IF(AND($J31<>"",T$4>=$J31,T$4<=IF($K31="",TODAY(),$K31),T$65=0),"●","") | U31: =IF(AND($J31<>"",U$4>=$J31,U$4<=IF($K31="",TODAY(),$K31),U$65=0),"●","") | ... AW31: =IF(AND($J31<>"",AW$4>=$J31,AW$4<=IF($K31="",TODAY(),$K31),AW$65=0),"●","") | AX31: Output: Table of PDB entries (method, resolution, construct). Accomplished when: One wild-type and one mutant entry are chosen, with the reasons recorded.
A32: 2.7 | B32: WP2 | C32: Archive the sources in references/ and maintain the reference list | D32: Bruno | E32: 1 | F32: 1 | G32: 2.3, 2.4 | H32: 46314 | I32: =WORKDAY(H32,E32-1,Holidays!$A$2:$A$40) -> 46314 | L32: Pending | M32: =IF(OR(K32="",I32=""),"",IF(K32>=I32,NETWORKDAYS(I32,K32,Holidays!$A$2:$A$40)-1,-(NETWORKDAYS(K32,I32,Holidays!$A$2:$A$40)-1))) | N32: =IF(AND($J32<>"",N$4>=$J32,N$4<=IF($K32="",TODAY(),$K32),N$65=0),"●","") | O32: =IF(AND($J32<>"",O$4>=$J32,O$4<=IF($K32="",TODAY(),$K32),O$65=0),"●","") | P32: =IF(AND($J32<>"",P$4>=$J32,P$4<=IF($K32="",TODAY(),$K32),P$65=0),"●","") | Q32: =IF(AND($J32<>"",Q$4>=$J32,Q$4<=IF($K32="",TODAY(),$K32),Q$65=0),"●","") | R32: =IF(AND($J32<>"",R$4>=$J32,R$4<=IF($K32="",TODAY(),$K32),R$65=0),"●","") | S32: =IF(AND($J32<>"",S$4>=$J32,S$4<=IF($K32="",TODAY(),$K32),S$65=0),"●","") | T32: =IF(AND($J32<>"",T$4>=$J32,T$4<=IF($K32="",TODAY(),$K32),T$65=0),"●","") | U32: =IF(AND($J32<>"",U$4>=$J32,U$4<=IF($K32="",TODAY(),$K32),U$65=0),"●","") | ... AW32: =IF(AND($J32<>"",AW$4>=$J32,AW$4<=IF($K32="",TODAY(),$K32),AW$65=0),"●","") | AX32: Output: PDFs and Mini Oxford reference list. Accomplished when: Every cited source is archived and listed in the required style.
A33: 2.8 | B33: WP2 | C33: Verify the sequence characterization independently: repeat the translation and the comparison of the four files | D33: Ettore | E33: 1 | F33: 1 | G33: 2.1 | H33: 46309 | I33: =WORKDAY(H33,E33-1,Holidays!$A$2:$A$40) -> 46309 | L33: Pending | M33: =IF(OR(K33="",I33=""),"",IF(K33>=I33,NETWORKDAYS(I33,K33,Holidays!$A$2:$A$40)-1,-(NETWORKDAYS(K33,I33,Holidays!$A$2:$A$40)-1))) | N33: =IF(AND($J33<>"",N$4>=$J33,N$4<=IF($K33="",TODAY(),$K33),N$65=0),"●","") | O33: =IF(AND($J33<>"",O$4>=$J33,O$4<=IF($K33="",TODAY(),$K33),O$65=0),"●","") | P33: =IF(AND($J33<>"",P$4>=$J33,P$4<=IF($K33="",TODAY(),$K33),P$65=0),"●","") | Q33: =IF(AND($J33<>"",Q$4>=$J33,Q$4<=IF($K33="",TODAY(),$K33),Q$65=0),"●","") | R33: =IF(AND($J33<>"",R$4>=$J33,R$4<=IF($K33="",TODAY(),$K33),R$65=0),"●","") | S33: =IF(AND($J33<>"",S$4>=$J33,S$4<=IF($K33="",TODAY(),$K33),S$65=0),"●","") | T33: =IF(AND($J33<>"",T$4>=$J33,T$4<=IF($K33="",TODAY(),$K33),T$65=0),"●","") | U33: =IF(AND($J33<>"",U$4>=$J33,U$4<=IF($K33="",TODAY(),$K33),U$65=0),"●","") | ... AW33: =IF(AND($J33<>"",AW$4>=$J33,AW$4<=IF($K33="",TODAY(),$K33),AW$65=0),"●","") | AX33: Output: Verification note. Accomplished when: The variant table of task 2.1 is confirmed, or each discrepancy is resolved with its owner.
A34: WP3 | B34: WP3 | C34: WP3 · Sequence and structure analysis | E34: =NETWORKDAYS(H34,I34,Holidays!$A$2:$A$40) -> 6 | H34: =MIN(H35:H43) -> 46309 | I34: =MAX(I35:I43) -> 46316
A35: 3.1 | B35: WP3 | C35: Pairwise alignments of human PK with the rat and mouse orthologs (protein and CDS) | D35: Leo | E35: 1 | F35: 1 | G35: 2.1, 2.5 | H35: 46310 | I35: =WORKDAY(H35,E35-1,Holidays!$A$2:$A$40) -> 46310 | L35: Pending | M35: =IF(OR(K35="",I35=""),"",IF(K35>=I35,NETWORKDAYS(I35,K35,Holidays!$A$2:$A$40)-1,-(NETWORKDAYS(K35,I35,Holidays!$A$2:$A$40)-1))) | N35: =IF(AND($J35<>"",N$4>=$J35,N$4<=IF($K35="",TODAY(),$K35),N$65=0),"●","") | O35: =IF(AND($J35<>"",O$4>=$J35,O$4<=IF($K35="",TODAY(),$K35),O$65=0),"●","") | P35: =IF(AND($J35<>"",P$4>=$J35,P$4<=IF($K35="",TODAY(),$K35),P$65=0),"●","") | Q35: =IF(AND($J35<>"",Q$4>=$J35,Q$4<=IF($K35="",TODAY(),$K35),Q$65=0),"●","") | R35: =IF(AND($J35<>"",R$4>=$J35,R$4<=IF($K35="",TODAY(),$K35),R$65=0),"●","") | S35: =IF(AND($J35<>"",S$4>=$J35,S$4<=IF($K35="",TODAY(),$K35),S$65=0),"●","") | T35: =IF(AND($J35<>"",T$4>=$J35,T$4<=IF($K35="",TODAY(),$K35),T$65=0),"●","") | U35: =IF(AND($J35<>"",U$4>=$J35,U$4<=IF($K35="",TODAY(),$K35),U$65=0),"●","") | ... AW35: =IF(AND($J35<>"",AW$4>=$J35,AW$4<=IF($K35="",TODAY(),$K35),AW$65=0),"●","") | AX35: Output: Alignments and identity table. Accomplished when: Percent identity and similarity are reported for each pair, with tool and parameters.
A36: 3.2 | B36: WP3 | C36: Multiple sequence alignment of human, rat, mouse, and dog PK; conservation of the substituted position and lineage of each difference | D36: Leo | E36: 2 | F36: 2 | G36: 3.1 | H36: 46311 | I36: =WORKDAY(H36,E36-1,Holidays!$A$2:$A$40) -> 46314 | L36: Pending | M36: =IF(OR(K36="",I36=""),"",IF(K36>=I36,NETWORKDAYS(I36,K36,Holidays!$A$2:$A$40)-1,-(NETWORKDAYS(K36,I36,Holidays!$A$2:$A$40)-1))) | N36: =IF(AND($J36<>"",N$4>=$J36,N$4<=IF($K36="",TODAY(),$K36),N$65=0),"●","") | O36: =IF(AND($J36<>"",O$4>=$J36,O$4<=IF($K36="",TODAY(),$K36),O$65=0),"●","") | P36: =IF(AND($J36<>"",P$4>=$J36,P$4<=IF($K36="",TODAY(),$K36),P$65=0),"●","") | Q36: =IF(AND($J36<>"",Q$4>=$J36,Q$4<=IF($K36="",TODAY(),$K36),Q$65=0),"●","") | R36: =IF(AND($J36<>"",R$4>=$J36,R$4<=IF($K36="",TODAY(),$K36),R$65=0),"●","") | S36: =IF(AND($J36<>"",S$4>=$J36,S$4<=IF($K36="",TODAY(),$K36),S$65=0),"●","") | T36: =IF(AND($J36<>"",T$4>=$J36,T$4<=IF($K36="",TODAY(),$K36),T$65=0),"●","") | U36: =IF(AND($J36<>"",U$4>=$J36,U$4<=IF($K36="",TODAY(),$K36),U$65=0),"●","") | ... AW36: =IF(AND($J36<>"",AW$4>=$J36,AW$4<=IF($K36="",TODAY(),$K36),AW$65=0),"●","") | AX36: Output: Alignment figure and conservation notes. Accomplished when: The residue at the substituted position is reported for every species, and the lineage of each change is stated.
A37: 3.3 | B37: WP3 | C37: Map the substituted residue on the wild-type structure: distances to the active site, the allosteric site, and the domain and subunit interfaces | D37: Pol | E37: 2 | F37: 2 | G37: 2.1, 2.6 | H37: 46309 | I37: =WORKDAY(H37,E37-1,Holidays!$A$2:$A$40) -> 46310 | L37: Pending | M37: =IF(OR(K37="",I37=""),"",IF(K37>=I37,NETWORKDAYS(I37,K37,Holidays!$A$2:$A$40)-1,-(NETWORKDAYS(K37,I37,Holidays!$A$2:$A$40)-1))) | N37: =IF(AND($J37<>"",N$4>=$J37,N$4<=IF($K37="",TODAY(),$K37),N$65=0),"●","") | O37: =IF(AND($J37<>"",O$4>=$J37,O$4<=IF($K37="",TODAY(),$K37),O$65=0),"●","") | P37: =IF(AND($J37<>"",P$4>=$J37,P$4<=IF($K37="",TODAY(),$K37),P$65=0),"●","") | Q37: =IF(AND($J37<>"",Q$4>=$J37,Q$4<=IF($K37="",TODAY(),$K37),Q$65=0),"●","") | R37: =IF(AND($J37<>"",R$4>=$J37,R$4<=IF($K37="",TODAY(),$K37),R$65=0),"●","") | S37: =IF(AND($J37<>"",S$4>=$J37,S$4<=IF($K37="",TODAY(),$K37),S$65=0),"●","") | T37: =IF(AND($J37<>"",T$4>=$J37,T$4<=IF($K37="",TODAY(),$K37),T$65=0),"●","") | U37: =IF(AND($J37<>"",U$4>=$J37,U$4<=IF($K37="",TODAY(),$K37),U$65=0),"●","") | ... AW37: =IF(AND($J37<>"",AW$4>=$J37,AW$4<=IF($K37="",TODAY(),$K37),AW$65=0),"●","") | AX37: Output: Annotated structure figure and distance table. Accomplished when: Distances are measured in a stated structure and chain.
A38: 3.4 | B38: WP3 | C38: Superpose the wild-type and mutant structures (repeated in the 22 Oct lab) | D38: Pol | E38: 2 | F38: 2 | G38: 3.3 | H38: 46311 | I38: =WORKDAY(H38,E38-1,Holidays!$A$2:$A$40) -> 46314 | L38: Pending | M38: =IF(OR(K38="",I38=""),"",IF(K38>=I38,NETWORKDAYS(I38,K38,Holidays!$A$2:$A$40)-1,-(NETWORKDAYS(K38,I38,Holidays!$A$2:$A$40)-1))) | N38: =IF(AND($J38<>"",N$4>=$J38,N$4<=IF($K38="",TODAY(),$K38),N$65=0),"●","") | O38: =IF(AND($J38<>"",O$4>=$J38,O$4<=IF($K38="",TODAY(),$K38),O$65=0),"●","") | P38: =IF(AND($J38<>"",P$4>=$J38,P$4<=IF($K38="",TODAY(),$K38),P$65=0),"●","") | Q38: =IF(AND($J38<>"",Q$4>=$J38,Q$4<=IF($K38="",TODAY(),$K38),Q$65=0),"●","") | R38: =IF(AND($J38<>"",R$4>=$J38,R$4<=IF($K38="",TODAY(),$K38),R$65=0),"●","") | S38: =IF(AND($J38<>"",S$4>=$J38,S$4<=IF($K38="",TODAY(),$K38),S$65=0),"●","") | T38: =IF(AND($J38<>"",T$4>=$J38,T$4<=IF($K38="",TODAY(),$K38),T$65=0),"●","") | U38: =IF(AND($J38<>"",U$4>=$J38,U$4<=IF($K38="",TODAY(),$K38),U$65=0),"●","") | ... AW38: =IF(AND($J38<>"",AW$4>=$J38,AW$4<=IF($K38="",TODAY(),$K38),AW$65=0),"●","") | AX38: Output: Superposition figure and RMSD values. Accomplished when: Global and local differences are quantified with the method stated.
A39: 3.5 | B39: WP3 | C39: Compare the human R-type and rat L-type structures around the substituted position | D39: Pol | E39: 1 | F39: 1 | G39: 3.4, 3.2 | H39: 46315 | I39: =WORKDAY(H39,E39-1,Holidays!$A$2:$A$40) -> 46315 | L39: Pending | M39: =IF(OR(K39="",I39=""),"",IF(K39>=I39,NETWORKDAYS(I39,K39,Holidays!$A$2:$A$40)-1,-(NETWORKDAYS(K39,I39,Holidays!$A$2:$A$40)-1))) | N39: =IF(AND($J39<>"",N$4>=$J39,N$4<=IF($K39="",TODAY(),$K39),N$65=0),"●","") | O39: =IF(AND($J39<>"",O$4>=$J39,O$4<=IF($K39="",TODAY(),$K39),O$65=0),"●","") | P39: =IF(AND($J39<>"",P$4>=$J39,P$4<=IF($K39="",TODAY(),$K39),P$65=0),"●","") | Q39: =IF(AND($J39<>"",Q$4>=$J39,Q$4<=IF($K39="",TODAY(),$K39),Q$65=0),"●","") | R39: =IF(AND($J39<>"",R$4>=$J39,R$4<=IF($K39="",TODAY(),$K39),R$65=0),"●","") | S39: =IF(AND($J39<>"",S$4>=$J39,S$4<=IF($K39="",TODAY(),$K39),S$65=0),"●","") | T39: =IF(AND($J39<>"",T$4>=$J39,T$4<=IF($K39="",TODAY(),$K39),T$65=0),"●","") | U39: =IF(AND($J39<>"",U$4>=$J39,U$4<=IF($K39="",TODAY(),$K39),U$65=0),"●","") | ... AW39: =IF(AND($J39<>"",AW$4>=$J39,AW$4<=IF($K39="",TODAY(),$K39),AW$65=0),"●","") | AX39: Output: Comparison figure and notes. Accomplished when: The local environment of the position is described in both species.
A40: 3.6 | B40: WP3 | C40: Assess pathogenicity: combine clinical, population, conservation, structural, and biochemical evidence | D40: Aarón | E40: 1 | F40: 1 | G40: 2.3, 2.4, 3.1 | H40: 46314 | I40: =WORKDAY(H40,E40-1,Holidays!$A$2:$A$40) -> 46314 | L40: Pending | M40: =IF(OR(K40="",I40=""),"",IF(K40>=I40,NETWORKDAYS(I40,K40,Holidays!$A$2:$A$40)-1,-(NETWORKDAYS(K40,I40,Holidays!$A$2:$A$40)-1))) | N40: =IF(AND($J40<>"",N$4>=$J40,N$4<=IF($K40="",TODAY(),$K40),N$65=0),"●","") | O40: =IF(AND($J40<>"",O$4>=$J40,O$4<=IF($K40="",TODAY(),$K40),O$65=0),"●","") | P40: =IF(AND($J40<>"",P$4>=$J40,P$4<=IF($K40="",TODAY(),$K40),P$65=0),"●","") | Q40: =IF(AND($J40<>"",Q$4>=$J40,Q$4<=IF($K40="",TODAY(),$K40),Q$65=0),"●","") | R40: =IF(AND($J40<>"",R$4>=$J40,R$4<=IF($K40="",TODAY(),$K40),R$65=0),"●","") | S40: =IF(AND($J40<>"",S$4>=$J40,S$4<=IF($K40="",TODAY(),$K40),S$65=0),"●","") | T40: =IF(AND($J40<>"",T$4>=$J40,T$4<=IF($K40="",TODAY(),$K40),T$65=0),"●","") | U40: =IF(AND($J40<>"",U$4>=$J40,U$4<=IF($K40="",TODAY(),$K40),U$65=0),"●","") | ... AW40: =IF(AND($J40<>"",AW$4>=$J40,AW$4<=IF($K40="",TODAY(),$K40),AW$65=0),"●","") | AX40: Output: Evidence summary table. Accomplished when: Each line of evidence is classified as measured result, hypothesis, or open question.
...

Sheet Members
A1: Members, roles, and distribution of the planned work (formulas read the Tasks sheet; Phase 0 excluded)
A3: Owner | B3: Full name | C3: Role | D3: Tasks owned | E3: Effort (working days) | F3: Completed | G3: In progress | H3: Incidents
A4: Aarón | B4: Aarón Godino Martínez | C4: Product Owner | D4: =COUNTIFS(Tasks!$D$5:$D$60,A4,Tasks!$B$5:$B$60,"<>P0",Tasks!$A$5:$A$60,"<>WP*") -> 8 | E4: =SUMIFS(Tasks!$F$5:$F$60,Tasks!$D$5:$D$60,A4,Tasks!$B$5:$B$60,"<>P0") -> 11 | F4: =COUNTIFS(Tasks!$D$5:$D$60,A4,Tasks!$L$5:$L$60,"Completed",Tasks!$B$5:$B$60,"<>P0") -> 0 | G4: =COUNTIFS(Tasks!$D$5:$D$60,A4,Tasks!$L$5:$L$60,"In progress") -> 0 | H4: =COUNTIFS(Tasks!$D$5:$D$60,A4,Tasks!$L$5:$L$60,"Incident") -> 0
A5: Bruno | B5: Bruno Carrasquilla | C5: Data and GitHub Manager | D5: =COUNTIFS(Tasks!$D$5:$D$60,A5,Tasks!$B$5:$B$60,"<>P0",Tasks!$A$5:$A$60,"<>WP*") -> 10 | E5: =SUMIFS(Tasks!$F$5:$F$60,Tasks!$D$5:$D$60,A5,Tasks!$B$5:$B$60,"<>P0") -> 12 | F5: =COUNTIFS(Tasks!$D$5:$D$60,A5,Tasks!$L$5:$L$60,"Completed",Tasks!$B$5:$B$60,"<>P0") -> 0 | G5: =COUNTIFS(Tasks!$D$5:$D$60,A5,Tasks!$L$5:$L$60,"In progress") -> 0 | H5: =COUNTIFS(Tasks!$D$5:$D$60,A5,Tasks!$L$5:$L$60,"Incident") -> 0
A6: Ettore | B6: Ettore Colombo | C6: Project Manager | D6: =COUNTIFS(Tasks!$D$5:$D$60,A6,Tasks!$B$5:$B$60,"<>P0",Tasks!$A$5:$A$60,"<>WP*") -> 9 | E6: =SUMIFS(Tasks!$F$5:$F$60,Tasks!$D$5:$D$60,A6,Tasks!$B$5:$B$60,"<>P0") -> 11 | F6: =COUNTIFS(Tasks!$D$5:$D$60,A6,Tasks!$L$5:$L$60,"Completed",Tasks!$B$5:$B$60,"<>P0") -> 0 | G6: =COUNTIFS(Tasks!$D$5:$D$60,A6,Tasks!$L$5:$L$60,"In progress") -> 0 | H6: =COUNTIFS(Tasks!$D$5:$D$60,A6,Tasks!$L$5:$L$60,"Incident") -> 0
A7: Leo | B7: Leo Nader Al Hourani | C7: Sequence Analyst | D7: =COUNTIFS(Tasks!$D$5:$D$60,A7,Tasks!$B$5:$B$60,"<>P0",Tasks!$A$5:$A$60,"<>WP*") -> 8 | E7: =SUMIFS(Tasks!$F$5:$F$60,Tasks!$D$5:$D$60,A7,Tasks!$B$5:$B$60,"<>P0") -> 11 | F7: =COUNTIFS(Tasks!$D$5:$D$60,A7,Tasks!$L$5:$L$60,"Completed",Tasks!$B$5:$B$60,"<>P0") -> 0 | G7: =COUNTIFS(Tasks!$D$5:$D$60,A7,Tasks!$L$5:$L$60,"In progress") -> 0 | H7: =COUNTIFS(Tasks!$D$5:$D$60,A7,Tasks!$L$5:$L$60,"Incident") -> 0
A8: Pol | B8: Pol Monllau | C8: Structure Analyst | D8: =COUNTIFS(Tasks!$D$5:$D$60,A8,Tasks!$B$5:$B$60,"<>P0",Tasks!$A$5:$A$60,"<>WP*") -> 7 | E8: =SUMIFS(Tasks!$F$5:$F$60,Tasks!$D$5:$D$60,A8,Tasks!$B$5:$B$60,"<>P0") -> 10 | F8: =COUNTIFS(Tasks!$D$5:$D$60,A8,Tasks!$L$5:$L$60,"Completed",Tasks!$B$5:$B$60,"<>P0") -> 0 | G8: =COUNTIFS(Tasks!$D$5:$D$60,A8,Tasks!$L$5:$L$60,"In progress") -> 0 | H8: =COUNTIFS(Tasks!$D$5:$D$60,A8,Tasks!$L$5:$L$60,"Incident") -> 0
A9: Total | D9: =SUM(D4:D8) -> 42 | E9: =SUM(E4:E8) -> 55 | F9: =SUM(F4:F8) -> 0 | G9: =SUM(G4:G8) -> 0 | H9: =SUM(H4:H8) -> 0

Sheet Milestones
A1: ID | B1: Milestone | C1: Planned date | D1: Real date | E1: Status | F1: Source | G1: Delay (working days)
A2: M0 | B2: Project presented; repository created | C2: 46282 | D2: 46282 | E2: Completed | F2: Overview; commits | G2: =IF(D2="","",IF(D2>=C2,NETWORKDAYS(C2,D2,Holidays!$A$2:$A$40)-1,-(NETWORKDAYS(D2,C2,Holidays!$A$2:$A$40)-1))) -> 0
A3: M1 | B3: Project plan submitted | C3: 46304 | E3: Pending | F3: Overview (18:00) | G3: =IF(D3="","",IF(D3>=C3,NETWORKDAYS(C3,D3,Holidays!$A$2:$A$40)-1,-(NETWORKDAYS(D3,C3,Holidays!$A$2:$A$40)-1)))
A4: M2 | B4: Data collected (variant, sequences, structures, literature) | C4: 46314 | E4: Pending | F4: after 2.7 | G4: =IF(D4="","",IF(D4>=C4,NETWORKDAYS(C4,D4,Holidays!$A$2:$A$40)-1,-(NETWORKDAYS(D4,C4,Holidays!$A$2:$A$40)-1)))
A5: M3 | B5: Analyses completed | C5: 46316 | E5: Pending | F5: after 3.8 | G5: =IF(D5="","",IF(D5>=C5,NETWORKDAYS(C5,D5,Holidays!$A$2:$A$40)-1,-(NETWORKDAYS(D5,C5,Holidays!$A$2:$A$40)-1)))
A6: M4 | B6: Project Status document discussed | C6: 46317 | E6: Pending | F6: Overview; Formal Requirements | G6: =IF(D6="","",IF(D6>=C6,NETWORKDAYS(C6,D6,Holidays!$A$2:$A$40)-1,-(NETWORKDAYS(D6,C6,Holidays!$A$2:$A$40)-1)))
A7: M5 | B7: Report draft complete | C7: 46321 | E7: Pending | F7: after 4.6 | G7: =IF(D7="","",IF(D7>=C7,NETWORKDAYS(C7,D7,Holidays!$A$2:$A$40)-1,-(NETWORKDAYS(D7,C7,Holidays!$A$2:$A$40)-1)))
A8: M6 | B8: Final report delivered | C8: 46323 | E8: Pending | F8: Overview (18:00) | G8: =IF(D8="","",IF(D8>=C8,NETWORKDAYS(C8,D8,Holidays!$A$2:$A$40)-1,-(NETWORKDAYS(D8,C8,Holidays!$A$2:$A$40)-1)))
A9: M7 | B9: Oral defence (all members) | C9: 46331 | E9: Pending | F9: Course schedule | G9: =IF(D9="","",IF(D9>=C9,NETWORKDAYS(C9,D9,Holidays!$A$2:$A$40)-1,-(NETWORKDAYS(D9,C9,Holidays!$A$2:$A$40)-1)))

Sheet Risks
A1: Risk register · Risk = Likelihood × Impact (1–3 each) · 1–2 Low · 3–5 Medium · 6–9 High
A3: ID | B3: Risk | C3: Likelihood | D3: Impact | E3: Score | F3: Level | G3: Owner | H3: Status | I3: Contingency plan | J3: Last review | K3: Notes
A4: R1 | B4: Commits made in bulk or near the deadlines | C4: 3 | D4: 3 | E4: =C4*D4 -> 9 | F4: =IF(E4>=6,"High",IF(E4>=3,"Medium","Low")) -> High | G4: Ettore | H4: Partly occurred | I4: Section-by-section commits on 9 Oct (1.1–1.5); commit after every work session; history reviewed weekly (1.7). | J4: 46303
A5: R2 | B5: Unequal contribution among members | C5: 3 | D5: 3 | E5: =C5*D5 -> 9 | F5: =IF(E5>=6,"High",IF(E5>=3,"Medium","Low")) -> High | G5: Pol | H5: Partly occurred | I5: Seven tasks per member; own commits; contributions recorded weekly; Authors' contributions section. | J5: 46303
A6: R3 | B6: Repository structure not compliant with the requirements | C6: 1 | D6: 3 | E6: =C6*D6 -> 3 | F6: =IF(E6>=6,"High",IF(E6>=3,"Medium","Low")) -> Medium | G6: Bruno | H6: Occurred | I6: Create report/, status/, gantt/, references/ on 9 Oct (1.1); check weekly (1.7). | J6: 46303
A7: R4 | B7: Project Status document or live Gantt chart not kept up to date | C7: 2 | D7: 2 | E7: =C7*D7 -> 4 | F7: =IF(E7>=6,"High",IF(E7>=3,"Medium","Low")) -> Medium | G7: Ettore | H7: Open | I7: Status document from 13 Oct (1.6); weekly update (1.7); final chart with real dates (1.9). | J7: 46303
A8: R5 | B8: Incorrect database record selected, or result misinterpreted | C8: 2 | D8: 3 | E8: =C8*D8 -> 6 | F8: =IF(E8>=6,"High",IF(E8>=3,"Medium","Low")) -> High | G8: Bruno | H8: Open | I8: Reviewed entries only; accession, access date and rationale recorded (2.2, 2.5, 2.6); second-member check, including the variant table (2.8). | J8: 46303
A9: R6 | B9: Alignment or structural results misinterpreted | C9: 2 | D9: 2 | E9: =C9*D9 -> 4 | F9: =IF(E9>=6,"High",IF(E9>=3,"Medium","Low")) -> Medium | G9: Pol | H9: Open | I9: Each analysis after its lab; questions to instructors; alignment repeated by a second member (3.9); superposition repeated in the 22 Oct lab (3.4). | J9: 46303
A10: R7 | B10: Species comparison insufficiently justified, or evolutionary changes inferred without an outgroup | C10: 1 | D10: 2 | E10: =C10*D10 -> 2 | F10: =IF(E10>=6,"High",IF(E10>=3,"Medium","Low")) -> Low | G10: Leo | H10: Open | I10: Reason for each species stated; dog as outgroup (2.5, 3.2); lineage claims only when the outgroup supports them. | J10: 46303
A11: R8 | B11: Parts developed in isolation; members aware only of their own tasks | C11: 2 | D11: 3 | E11: =C11*D11 -> 6 | F11: =IF(E11>=6,"High",IF(E11>=3,"Medium","Low")) -> High | G11: Leo | H11: Open | I11: Synthesis meeting (3.8); full read-through (4.7); each member presents their own part (4.10–4.14); cross-questioning rehearsal (4.16). | J11: 46303
A12: R9 | B12: Statements supported by weak or unverified sources, including GenAI output | C12: 2 | D12: 2 | E12: =C12*D12 -> 4 | F12: =IF(E12>=6,"High",IF(E12>=3,"Medium","Low")) -> Medium | G12: Aarón | H12: Open | I12: Primary articles for facts, reviews for context; GenAI output verified at source; sources archived (2.7). | J12: 46303
A13: R10 | B13: Report format, length limits, or delivery deadline not met | C13: 2 | D13: 3 | E13: =C13*D13 -> 6 | F13: =IF(E13>=6,"High",IF(E13>=3,"Medium","Low")) -> High | G13: Aarón | H13: Open | I13: Word budget; format check 27 Oct (4.8); assembly 26 Oct (4.6); final commit by 12:00 on 28 Oct (4.9). | J13: 46303

Sheet Holidays
A1: Date | B1: Holiday
A2: 46289 | B2: Local holiday | D2: Add any further non-working day in column A; all working-day formulas use rows 2–40.
A3: 46307 | B3: National holiday
