Workbook

Sheet Read me
A1: 11DP-C · Live Gantt chart and Project Status
A2: Generated on 8 October 2026 from the plan submitted on 9 October (baseline). From then on, update it by hand.
A4: What to edit
A5: Only the yellow cells. Each owner updates their own rows in the Project Status sheet: Real Start, Real Finish, Status, Notes;
A6: the Tasks sheet (Gantt chart), the delays, and the Members totals update from it automatically. Also: Real date and Status (Milestones);
A7: Likelihood, Impact, Status, Last review, Notes (Risks). Planned dates are the 9 October baseline and must not be changed.
A8: Example: when Leo starts task 2.1 on Tue 13 Oct, he writes 13/10/2026 in Real Start (Project Status) and sets Status to 'In progress';
A9: when he finishes, he writes the Real end and sets 'Completed'. Delay is computed automatically (negative = early).
A10: Status values (Formal Requirements, Project Status Document): Backlog, Pending, In progress, Completed, Incident, Canceled.
A12: How to read the chart (Tasks sheet)
A13: Bar fill = phase of the planned task: grey Phase 0 (completed), blue WP1, teal WP2, amber WP3, purple WP4.
A14: Line under the bar = owner: red Aarón, lime Bruno, black Ettore, magenta Leo, azure Pol, grey all members.
... A26: Yellow = cell to edit

Sheet Project Status
A1: Project Status · Group 11DP-C · Pyruvate Kinase Deficiency
A2: Task tracking — Updated up to | B2: 46321 | C2: Edit only the yellow cells of your own tasks: Real Start, Real Finish, Status, Notes. Planned dates come from the 9 October baseline.
A4: Task | B4: Resp. | C4: Plan. Start Date | D4: Plan. Finish Date | E4: Real Start Date | F4: Real Finish Date | G4: Status | H4: Notes
A5: Phase 0 · Project start-up (completed)
A6: 0.1 Create the GitHub repository and write the README | B6: Leo | C6: =Tasks!H6 -> 46282 | D6: =Tasks!I6 -> 46282 | E6: 46282 | F6: 46282 | G6: Completed | H6: Evidence: Commits of 17 Sep.
A7: 0.2 Create the report file and the folder structure | B7: Ettore | C7: =Tasks!H7 -> 46282 | D7: =Tasks!I7 -> 46282 | E7: 46282 | F7: 46282 | G7: Completed | H7: Evidence: Commits of 17 Sep.
A8: 0.3 Study the course instructions and the disease | B8: All | C8: =Tasks!H8 -> 46286 | D8: =Tasks!I8 -> 46303 | E8: 46286 | F8: 46303 | G8: Completed | H8: Evidence: Reported by the team.
A9: 0.4 Team meeting 1 (after class) | B9: All | C9: =Tasks!H9 -> 46286 | D9: =Tasks!I9 -> 46286 | E9: 46286 | F9: 46286 | G9: Completed | H9: Evidence: Reported by the team.
A10: 0.5 Format the report file | B10: Aarón | C10: =Tasks!H10 -> 46293 | D10: =Tasks!I10 -> 46293 | E10: 46293 | F10: 46293 | G10: Completed | H10: Evidence: Commit of 28 Sep.
A11: 0.6 Team meeting 2 (after class) | B11: All | C11: =Tasks!H11 -> 46293 | D11: =Tasks!I11 -> 46293 | E11: 46293 | F11: 46293 | G11: Completed | H11: Evidence: Reported by the team.
A12: 0.7 Team meeting 3 (after class) | B12: All | C12: =Tasks!H12 -> 46300 | D12: =Tasks!I12 -> 46300 | E12: 46300 | F12: 46300 | G12: Completed | H12: Evidence: Reported by the team.
A13: 0.8 Draft the project plan (introduction, objectives, Gantt chart, risks) | B13: Ettore | C13: =Tasks!H13 -> 46300 | D13: =Tasks!I13 -> 46303 | E13: 46300 | F13: 46303 | G13: Completed | H13: Evidence: Draft files.
A14: 0.9 Team meeting 4 (after class): review of the draft plan; decision to submit it through GitHub rather than as a PDF | B14: All | C14: =Tasks!H14 -> 46303 | D14: =Tasks!I14 -> 46303 | E14: 46303 | F14: 46303 | G14: Completed | H14: Evidence: Reported by the team.
A15: WP1 · Project management and GitHub
A16: 1.1 Review and commit the introduction (PKD_1); create the folders report/, status/, gantt/, and references/ | B16: Ettore | C16: =Tasks!H16 -> 46304 | D16: =Tasks!I16 -> 46304 | E16: 46304 | F16: 46304 | G16: Completed | H16: Introduction committed by Ettore on 9 Oct; the folders gantt/, status/, references/, and report/ were created by Leo and Bruno on 8 Oct.
A17: 1.2 Review and commit the overview and team section (PKD_2); submit the repository URL on Moodle | B17: Aarón | C17: =Tasks!H17 -> 46304 | D17: =Tasks!I17 -> 46304 | E17: 46303 | F17: 46304 | G17: Completed | H17: PKD_2 committed by Aarón on 8 Oct; repository URL submitted on Moodle by Ettore on 9 Oct.
A18: 1.3 Review and commit the Gantt chart (PKD_3) | B18: Bruno | C18: =Tasks!H18 -> 46304 | D18: =Tasks!I18 -> 46304 | E18: 46303 | F18: 46303 | G18: Completed | H18: Committed by Leo on 8 Oct and edited by Pol; owner after the role swap: Bruno.
A19: 1.4 Review and commit the task details (PKD_4) | B19: Pol | C19: =Tasks!H19 -> 46304 | D19: =Tasks!I19 -> 46304 | E19: 46303 | F19: 46303 | G19: Completed | H19: Committed by Pol on 8 Oct; owner columns corrected for the role swap.
A20: 1.5 Review and commit the risk analysis and references (PKD_5, PKD_6) | B20: Leo | C20: =Tasks!H20 -> 46304 | D20: =Tasks!I20 -> 46304 | E20: 46303 | F20: 46304 | G20: Completed | H20: Committed by Bruno (PKD_6 on 8 Oct, PKD_5 on 9 Oct), references updated by Ettore on 9 Oct; owner after the role swap: Leo.
A21: 1.6 Create the Project Status document | B21: Ettore | C21: =Tasks!H21 -> 46308 | D21: =Tasks!I21 -> 46308 | E21: 46304 | F21: 46304 | G21: Completed | H21: Created by Ettore on 9 Oct (status/Project_Status_2026_10_09.md).
A22: 1.7 Weekly status update and team meeting (Fridays 16 and 23 Oct) | B22: Ettore | C22: =Tasks!H22 -> 46311 | D22: =Tasks!I22 -> 46318 | E22: 46311 | F22: 46318 | G22: Completed | H22: Meetings of 16 and 23 Oct held.
A23: 1.8 Prepare the Project Status document for the 22 Oct discussion | B23: Ettore | C23: =Tasks!H23 -> 46315 | D23: =Tasks!I23 -> 46315 | E23: 46315 | F23: 46315 | G23: Completed | H23: Project Status of 20 Oct, discussed in class on 22 Oct.
A24: 1.9 Produce the final Gantt chart with real dates (live version) | B24: Ettore | C24: =Tasks!H24 -> 46322 | D24: =Tasks!I24 -> 46322 | E24: 46321 | F24: 46321 | G24: Completed | H24: Final Gantt chart and Project Status of 26 Oct (gantt/ and status/).
A25: WP2 · Data sources, literature, and sequences
A26: 2.1 Characterize the supplied sequences: translate both CDSs, compare wild type and mutant, and name the variant in HGVS nomenclature | B26: Bruno | C26: =Tasks!H26 -> 46308 | D26: =Tasks!I26 -> 46308 | E26: 46318 | F26: 46319 | G26: Completed | H26: Both CDSs translated; one difference, c.1456C>T, p.(Arg486Trp).
A27: 2.2 Identify the gene, the isoform, and the reference entries (HGNC, NCBI Gene, UniProt) | B27: Leo | C27: =Tasks!H27 -> 46308 | D27: =Tasks!I27 -> 46308 | E27: 46319 | F27: 46319 | G27: Completed | H27: Reference records in analysis/sequence/raw/.
A28: 2.3 Collect clinical and population evidence on the variant (ClinVar, gnomAD, OMIM, literature) | B28: Leo | C28: =Tasks!H28 -> 46310 | D28: =Tasks!I28 -> 46311 | E28: 46319 | F28: 46319 | G28: Completed | H28: ClinVar and gnomAD evidence; Table 1.
A29: 2.4 Review the literature on PK and PKD: normal function, mechanism, inheritance, and clinical features | B29: Aarón | C29: =Tasks!H29 -> 46308 | D29: =Tasks!I29 -> 46310 | E29: 46318 | F29: 46321 | G29: Completed | H29: Sources of the Background checked; cited articles saved in references/articles/ by Aarón.
A30: 2.5 Retrieve the reviewed orthologous sequences: rat, mouse, and dog (outgroup) | B30: Leo | C30: =Tasks!H30 -> 46309 | D30: =Tasks!I30 -> 46309 | E30: 46319 | F30: 46319 | G30: Completed | H30: Rat, mouse, and dog PKLR and the vertebrate panel.
A31: 2.6 Select the experimental structures: wild-type and mutant human R-type PK; rat PK | B31: Pol | C31: =Tasks!H31 -> 46308 | D31: =Tasks!I31 -> 46308 | E31: 46319 | F31: 46321 | G31: Completed | H31: Wild-type PDB 2VGB and mutant PDB 2VGI; no rat structure used (see 3.5).
A32: 2.7 Archive the sources in references/ and maintain the reference list | B32: Leo | C32: =Tasks!H32 -> 46314 | D32: =Tasks!I32 -> 46314 | E32: 46319 | F32: 46321 | G32: Completed | H32: Reference list completed; database records in references/databases/.
A33: 2.8 Verify the sequence characterization independently: repeat the translation and the comparison of the four files | B33: Ettore | C33: =Tasks!H33 -> 46309 | D33: =Tasks!I33 -> 46309 | E33: 46319 | F33: 46319 | G33: Completed | H33: Translation, variant, and identities recomputed by independent methods: all agree.
A34: WP3 · Sequence and structure analysis
A35: 3.1 Pairwise alignments of human PK with the rat and mouse orthologs (protein and CDS) | B35: Bruno | C35: =Tasks!H35 -> 46310 | D35: =Tasks!I35 -> 46310 | E35: 46318 | F35: 46319 | G35: Completed | H35: Human PKLR vs rat, mouse, and dog: protein identity 91.1%, 91.6%, 92.5%.
A36: 3.2 Multiple sequence alignment of human, rat, mouse, and dog PK; conservation of the substituted position and lineage of each difference | B36: Bruno | C36: =Tasks!H36 -> 46311 | D36: =Tasks!I36 -> 46314 | E36: 46319 | F36: 46319 | G36: Completed | H36: Multiple alignments; residue 486 by species; Figure 1, Table 2.
A37: 3.3 Map the substituted residue on the wild-type structure: distances to the active site, the allosteric site, and the domain and subunit interfaces | B37: Pol | C37: =Tasks!H37 -> 46309 | D37: =Tasks!I37 -> 46310 | E37: 46319 | F37: 46319 | G37: Completed | H37: Arg486 in the C domain; distances to the FBP and active sites.
A38: 3.4 Superpose the wild-type and mutant structures (repeated in the 22 Oct lab) | B38: Pol | C38: =Tasks!H38 -> 46311 | D38: =Tasks!I38 -> 46314 | E38: 46319 | F38: 46319 | G38: Completed | H38: Wild-type and R486W structures superposed.
A39: 3.5 Compare the human R-type and rat L-type structures around the substituted position | B39: Pol | C39: =Tasks!H39 -> 46315 | D39: =Tasks!I39 -> 46315 | E39: 46319 | G39: Canceled | H39: Not done: no functional data exist on the rat enzyme at this position or on Gln at 486 in humans, so a structural comparison could not be interpreted in terms of function.
A40: 3.6 Assess pathogenicity: combine clinical, population, conservation, structural, and biochemical evidence | B40: Aarón | C40: =Tasks!H40 -> 46314 | D40: =Tasks!I40 -> 46314 | E40: 46321 | F40: 46321 | G40: Completed | H40: Done in the Results and Discussion of the report (Discussion written by Ettore).
A41: 3.7 Explain the impact on the patient: from enzyme activity to red-cell ATP, haemolysis, and clinical severity | B41: Aarón | C41: =Tasks!H41 -> 46315 | D41: =Tasks!I41 -> 46315 | E41: 46321 | F41: 46321 | G41: Completed | H41: Done in the Discussion of the report (written by Ettore).
...

Sheet Tasks
A1: 11DP-C · Pyruvate Kinase Deficiency: from a PKLR variant to haemolytic anaemia · live Gantt chart and Project Status
A2: Planned dates = baseline of 9 October 2026. Real dates and status are read from the Project Status sheet: edit them there, not here. Bar fill = phase (planned); line under the bar = owner; ● = real execution.
N3: 46279 | P3: 46286 | U3: 46293 | Z3: 46300 | AE3: 46307 | AJ3: 46314 | AO3: 46321 | AT3: 46328
A4: ID | B4: Phase | C4: Task | D4: Owner | E4: Duration (working days) | F4: Effort (days) | G4: Predecessors | H4: Planned start | I4: Planned end | J4: Real start | K4: Real end | L4: Status | M4: Delay (working days) | N4: 46282 | O4: 46283 | P4: 46286 | Q4: 46287 | R4: 46288 | S4: 46289 | T4: 46290 | U4: 46293 | V4: 46294 | W4: 46295 | X4: 46296 | Y4: 46297 | Z4: 46300 | AA4: 46301 | AB4: 46302 | AC4: 46303 | AD4: 46304 | AE4: 46307 | AF4: 46308 | AG4: 46309 | AH4: 46310 | AI4: 46311 | AJ4: 46314 | AK4: 46315 | AL4: 46316 | AM4: 46317 | AN4: 46318 | AO4: 46321 | AP4: 46322 | AQ4: 46323 | AR4: 46324 | AS4: 46325 | AT4: 46328 | AU4: 46329 | AV4: 46330 | AW4: 46331 | AX4: Output and completion criterion (baseline)
A5: P0 | B5: P0 | C5: Phase 0 · Project start-up (completed) | E5: =NETWORKDAYS(H5,I5,Holidays!$A$2:$A$40) -> 15 | H5: =MIN(H6:H14) -> 46282 | I5: =MAX(I6:I14) -> 46303
A6: 0.1 | B6: P0 | C6: Create the GitHub repository and write the README | D6: Leo | E6: 1 | F6: 1 | H6: 46282 | I6: =WORKDAY(H6,E6-1,Holidays!$A$2:$A$40) -> 46282 | J6: =IF('Project Status'!E6="","",'Project Status'!E6) -> 46282 | K6: =IF('Project Status'!F6="","",'Project Status'!F6) -> 46282 | L6: =IF('Project Status'!G6="","",'Project Status'!G6) -> Completed | M6: =IF(OR(K6="",I6=""),"",IF(K6>=I6,NETWORKDAYS(I6,K6,Holidays!$A$2:$A$40)-1,-(NETWORKDAYS(K6,I6,Holidays!$A$2:$A$40)-1))) -> 0 | N6: =IF(AND($J6<>"",N$4>=$J6,N$4<=IF($K6="",TODAY(),$K6),N$67=0),"●","") -> ● | O6: =IF(AND($J6<>"",O$4>=$J6,O$4<=IF($K6="",TODAY(),$K6),O$67=0),"●","") | P6: =IF(AND($J6<>"",P$4>=$J6,P$4<=IF($K6="",TODAY(),$K6),P$67=0),"●","") | Q6: =IF(AND($J6<>"",Q$4>=$J6,Q$4<=IF($K6="",TODAY(),$K6),Q$67=0),"●","") | R6: =IF(AND($J6<>"",R$4>=$J6,R$4<=IF($K6="",TODAY(),$K6),R$67=0),"●","") | S6: =IF(AND($J6<>"",S$4>=$J6,S$4<=IF($K6="",TODAY(),$K6),S$67=0),"●","") | T6: =IF(AND($J6<>"",T$4>=$J6,T$4<=IF($K6="",TODAY(),$K6),T$67=0),"●","") | U6: =IF(AND($J6<>"",U$4>=$J6,U$4<=IF($K6="",TODAY(),$K6),U$67=0),"●","") | ... AW6: =IF(AND($J6<>"",AW$4>=$J6,AW$4<=IF($K6="",TODAY(),$K6),AW$67=0),"●","") | AX6: Output: Repository 11DP-C_Pyruvate-Kinase-Deficiency_IB_2026. Evidence: Commits of 17 Sep.
A7: 0.2 | B7: P0 | C7: Create the report file and the folder structure | D7: Ettore | E7: 1 | F7: 1 | H7: 46282 | I7: =WORKDAY(H7,E7-1,Holidays!$A$2:$A$40) -> 46282 | J7: =IF('Project Status'!E7="","",'Project Status'!E7) -> 46282 | K7: =IF('Project Status'!F7="","",'Project Status'!F7) -> 46282 | L7: =IF('Project Status'!G7="","",'Project Status'!G7) -> Completed | M7: =IF(OR(K7="",I7=""),"",IF(K7>=I7,NETWORKDAYS(I7,K7,Holidays!$A$2:$A$40)-1,-(NETWORKDAYS(K7,I7,Holidays!$A$2:$A$40)-1))) -> 0 | N7: =IF(AND($J7<>"",N$4>=$J7,N$4<=IF($K7="",TODAY(),$K7),N$67=0),"●","") -> ● | O7: =IF(AND($J7<>"",O$4>=$J7,O$4<=IF($K7="",TODAY(),$K7),O$67=0),"●","") | P7: =IF(AND($J7<>"",P$4>=$J7,P$4<=IF($K7="",TODAY(),$K7),P$67=0),"●","") | Q7: =IF(AND($J7<>"",Q$4>=$J7,Q$4<=IF($K7="",TODAY(),$K7),Q$67=0),"●","") | R7: =IF(AND($J7<>"",R$4>=$J7,R$4<=IF($K7="",TODAY(),$K7),R$67=0),"●","") | S7: =IF(AND($J7<>"",S$4>=$J7,S$4<=IF($K7="",TODAY(),$K7),S$67=0),"●","") | T7: =IF(AND($J7<>"",T$4>=$J7,T$4<=IF($K7="",TODAY(),$K7),T$67=0),"●","") | U7: =IF(AND($J7<>"",U$4>=$J7,U$4<=IF($K7="",TODAY(),$K7),U$67=0),"●","") | ... AW7: =IF(AND($J7<>"",AW$4>=$J7,AW$4<=IF($K7="",TODAY(),$K7),AW$67=0),"●","") | AX7: Output: `report.md`, `figures/`. Evidence: Commits of 17 Sep.
A8: 0.3 | B8: P0 | C8: Study the course instructions and the disease | D8: All | E8: 13 | F8: 13 | H8: 46286 | I8: =WORKDAY(H8,E8-1,Holidays!$A$2:$A$40) -> 46303 | J8: =IF('Project Status'!E8="","",'Project Status'!E8) -> 46286 | K8: =IF('Project Status'!F8="","",'Project Status'!F8) -> 46303 | L8: =IF('Project Status'!G8="","",'Project Status'!G8) -> Completed | M8: =IF(OR(K8="",I8=""),"",IF(K8>=I8,NETWORKDAYS(I8,K8,Holidays!$A$2:$A$40)-1,-(NETWORKDAYS(K8,I8,Holidays!$A$2:$A$40)-1))) -> 0 | N8: =IF(AND($J8<>"",N$4>=$J8,N$4<=IF($K8="",TODAY(),$K8),N$67=0),"●","") | O8: =IF(AND($J8<>"",O$4>=$J8,O$4<=IF($K8="",TODAY(),$K8),O$67=0),"●","") | P8: =IF(AND($J8<>"",P$4>=$J8,P$4<=IF($K8="",TODAY(),$K8),P$67=0),"●","") -> ● | Q8: =IF(AND($J8<>"",Q$4>=$J8,Q$4<=IF($K8="",TODAY(),$K8),Q$67=0),"●","") -> ● | R8: =IF(AND($J8<>"",R$4>=$J8,R$4<=IF($K8="",TODAY(),$K8),R$67=0),"●","") -> ● | S8: =IF(AND($J8<>"",S$4>=$J8,S$4<=IF($K8="",TODAY(),$K8),S$67=0),"●","") | T8: =IF(AND($J8<>"",T$4>=$J8,T$4<=IF($K8="",TODAY(),$K8),T$67=0),"●","") -> ● | U8: =IF(AND($J8<>"",U$4>=$J8,U$4<=IF($K8="",TODAY(),$K8),U$67=0),"●","") -> ● | ... AW8: =IF(AND($J8<>"",AW$4>=$J8,AW$4<=IF($K8="",TODAY(),$K8),AW$67=0),"●","") | AX8: Output: Shared understanding of the task. Evidence: Reported by the team.
A9: 0.4 | B9: P0 | C9: Team meeting 1 (after class) | D9: All | E9: 1 | F9: 1 | H9: 46286 | I9: =WORKDAY(H9,E9-1,Holidays!$A$2:$A$40) -> 46286 | J9: =IF('Project Status'!E9="","",'Project Status'!E9) -> 46286 | K9: =IF('Project Status'!F9="","",'Project Status'!F9) -> 46286 | L9: =IF('Project Status'!G9="","",'Project Status'!G9) -> Completed | M9: =IF(OR(K9="",I9=""),"",IF(K9>=I9,NETWORKDAYS(I9,K9,Holidays!$A$2:$A$40)-1,-(NETWORKDAYS(K9,I9,Holidays!$A$2:$A$40)-1))) -> 0 | N9: =IF(AND($J9<>"",N$4>=$J9,N$4<=IF($K9="",TODAY(),$K9),N$67=0),"●","") | O9: =IF(AND($J9<>"",O$4>=$J9,O$4<=IF($K9="",TODAY(),$K9),O$67=0),"●","") | P9: =IF(AND($J9<>"",P$4>=$J9,P$4<=IF($K9="",TODAY(),$K9),P$67=0),"●","") -> ● | Q9: =IF(AND($J9<>"",Q$4>=$J9,Q$4<=IF($K9="",TODAY(),$K9),Q$67=0),"●","") | R9: =IF(AND($J9<>"",R$4>=$J9,R$4<=IF($K9="",TODAY(),$K9),R$67=0),"●","") | S9: =IF(AND($J9<>"",S$4>=$J9,S$4<=IF($K9="",TODAY(),$K9),S$67=0),"●","") | T9: =IF(AND($J9<>"",T$4>=$J9,T$4<=IF($K9="",TODAY(),$K9),T$67=0),"●","") | U9: =IF(AND($J9<>"",U$4>=$J9,U$4<=IF($K9="",TODAY(),$K9),U$67=0),"●","") | ... AW9: =IF(AND($J9<>"",AW$4>=$J9,AW$4<=IF($K9="",TODAY(),$K9),AW$67=0),"●","") | AX9: Output: Organization of the work. Evidence: Reported by the team.
A10: 0.5 | B10: P0 | C10: Format the report file | D10: Aarón | E10: 1 | F10: 1 | H10: 46293 | I10: =WORKDAY(H10,E10-1,Holidays!$A$2:$A$40) -> 46293 | J10: =IF('Project Status'!E10="","",'Project Status'!E10) -> 46293 | K10: =IF('Project Status'!F10="","",'Project Status'!F10) -> 46293 | L10: =IF('Project Status'!G10="","",'Project Status'!G10) -> Completed | M10: =IF(OR(K10="",I10=""),"",IF(K10>=I10,NETWORKDAYS(I10,K10,Holidays!$A$2:$A$40)-1,-(NETWORKDAYS(K10,I10,Holidays!$A$2:$A$40)-1))) -> 0 | N10: =IF(AND($J10<>"",N$4>=$J10,N$4<=IF($K10="",TODAY(),$K10),N$67=0),"●","") | O10: =IF(AND($J10<>"",O$4>=$J10,O$4<=IF($K10="",TODAY(),$K10),O$67=0),"●","") | P10: =IF(AND($J10<>"",P$4>=$J10,P$4<=IF($K10="",TODAY(),$K10),P$67=0),"●","") | Q10: =IF(AND($J10<>"",Q$4>=$J10,Q$4<=IF($K10="",TODAY(),$K10),Q$67=0),"●","") | R10: =IF(AND($J10<>"",R$4>=$J10,R$4<=IF($K10="",TODAY(),$K10),R$67=0),"●","") | S10: =IF(AND($J10<>"",S$4>=$J10,S$4<=IF($K10="",TODAY(),$K10),S$67=0),"●","") | T10: =IF(AND($J10<>"",T$4>=$J10,T$4<=IF($K10="",TODAY(),$K10),T$67=0),"●","") | U10: =IF(AND($J10<>"",U$4>=$J10,U$4<=IF($K10="",TODAY(),$K10),U$67=0),"●","") -> ● | ... AW10: =IF(AND($J10<>"",AW$4>=$J10,AW$4<=IF($K10="",TODAY(),$K10),AW$67=0),"●","") | AX10: Output: Formatted `report.md`. Evidence: Commit of 28 Sep.
A11: 0.6 | B11: P0 | C11: Team meeting 2 (after class) | D11: All | E11: 1 | F11: 1 | H11: 46293 | I11: =WORKDAY(H11,E11-1,Holidays!$A$2:$A$40) -> 46293 | J11: =IF('Project Status'!E11="","",'Project Status'!E11) -> 46293 | K11: =IF('Project Status'!F11="","",'Project Status'!F11) -> 46293 | L11: =IF('Project Status'!G11="","",'Project Status'!G11) -> Completed | M11: =IF(OR(K11="",I11=""),"",IF(K11>=I11,NETWORKDAYS(I11,K11,Holidays!$A$2:$A$40)-1,-(NETWORKDAYS(K11,I11,Holidays!$A$2:$A$40)-1))) -> 0 | N11: =IF(AND($J11<>"",N$4>=$J11,N$4<=IF($K11="",TODAY(),$K11),N$67=0),"●","") | O11: =IF(AND($J11<>"",O$4>=$J11,O$4<=IF($K11="",TODAY(),$K11),O$67=0),"●","") | P11: =IF(AND($J11<>"",P$4>=$J11,P$4<=IF($K11="",TODAY(),$K11),P$67=0),"●","") | Q11: =IF(AND($J11<>"",Q$4>=$J11,Q$4<=IF($K11="",TODAY(),$K11),Q$67=0),"●","") | R11: =IF(AND($J11<>"",R$4>=$J11,R$4<=IF($K11="",TODAY(),$K11),R$67=0),"●","") | S11: =IF(AND($J11<>"",S$4>=$J11,S$4<=IF($K11="",TODAY(),$K11),S$67=0),"●","") | T11: =IF(AND($J11<>"",T$4>=$J11,T$4<=IF($K11="",TODAY(),$K11),T$67=0),"●","") | U11: =IF(AND($J11<>"",U$4>=$J11,U$4<=IF($K11="",TODAY(),$K11),U$67=0),"●","") -> ● | ... AW11: =IF(AND($J11<>"",AW$4>=$J11,AW$4<=IF($K11="",TODAY(),$K11),AW$67=0),"●","") | AX11: Output: Organization of the work. Evidence: Reported by the team.
A12: 0.7 | B12: P0 | C12: Team meeting 3 (after class) | D12: All | E12: 1 | F12: 1 | H12: 46300 | I12: =WORKDAY(H12,E12-1,Holidays!$A$2:$A$40) -> 46300 | J12: =IF('Project Status'!E12="","",'Project Status'!E12) -> 46300 | K12: =IF('Project Status'!F12="","",'Project Status'!F12) -> 46300 | L12: =IF('Project Status'!G12="","",'Project Status'!G12) -> Completed | M12: =IF(OR(K12="",I12=""),"",IF(K12>=I12,NETWORKDAYS(I12,K12,Holidays!$A$2:$A$40)-1,-(NETWORKDAYS(K12,I12,Holidays!$A$2:$A$40)-1))) -> 0 | N12: =IF(AND($J12<>"",N$4>=$J12,N$4<=IF($K12="",TODAY(),$K12),N$67=0),"●","") | O12: =IF(AND($J12<>"",O$4>=$J12,O$4<=IF($K12="",TODAY(),$K12),O$67=0),"●","") | P12: =IF(AND($J12<>"",P$4>=$J12,P$4<=IF($K12="",TODAY(),$K12),P$67=0),"●","") | Q12: =IF(AND($J12<>"",Q$4>=$J12,Q$4<=IF($K12="",TODAY(),$K12),Q$67=0),"●","") | R12: =IF(AND($J12<>"",R$4>=$J12,R$4<=IF($K12="",TODAY(),$K12),R$67=0),"●","") | S12: =IF(AND($J12<>"",S$4>=$J12,S$4<=IF($K12="",TODAY(),$K12),S$67=0),"●","") | T12: =IF(AND($J12<>"",T$4>=$J12,T$4<=IF($K12="",TODAY(),$K12),T$67=0),"●","") | U12: =IF(AND($J12<>"",U$4>=$J12,U$4<=IF($K12="",TODAY(),$K12),U$67=0),"●","") | ... AW12: =IF(AND($J12<>"",AW$4>=$J12,AW$4<=IF($K12="",TODAY(),$K12),AW$67=0),"●","") | AX12: Output: Organization of the work. Evidence: Reported by the team.
A13: 0.8 | B13: P0 | C13: Draft the project plan (introduction, objectives, Gantt chart, risks) | D13: Ettore | E13: 4 | F13: 4 | H13: 46300 | I13: =WORKDAY(H13,E13-1,Holidays!$A$2:$A$40) -> 46303 | J13: =IF('Project Status'!E13="","",'Project Status'!E13) -> 46300 | K13: =IF('Project Status'!F13="","",'Project Status'!F13) -> 46303 | L13: =IF('Project Status'!G13="","",'Project Status'!G13) -> Completed | M13: =IF(OR(K13="",I13=""),"",IF(K13>=I13,NETWORKDAYS(I13,K13,Holidays!$A$2:$A$40)-1,-(NETWORKDAYS(K13,I13,Holidays!$A$2:$A$40)-1))) -> 0 | N13: =IF(AND($J13<>"",N$4>=$J13,N$4<=IF($K13="",TODAY(),$K13),N$67=0),"●","") | O13: =IF(AND($J13<>"",O$4>=$J13,O$4<=IF($K13="",TODAY(),$K13),O$67=0),"●","") | P13: =IF(AND($J13<>"",P$4>=$J13,P$4<=IF($K13="",TODAY(),$K13),P$67=0),"●","") | Q13: =IF(AND($J13<>"",Q$4>=$J13,Q$4<=IF($K13="",TODAY(),$K13),Q$67=0),"●","") | R13: =IF(AND($J13<>"",R$4>=$J13,R$4<=IF($K13="",TODAY(),$K13),R$67=0),"●","") | S13: =IF(AND($J13<>"",S$4>=$J13,S$4<=IF($K13="",TODAY(),$K13),S$67=0),"●","") | T13: =IF(AND($J13<>"",T$4>=$J13,T$4<=IF($K13="",TODAY(),$K13),T$67=0),"●","") | U13: =IF(AND($J13<>"",U$4>=$J13,U$4<=IF($K13="",TODAY(),$K13),U$67=0),"●","") | ... AW13: =IF(AND($J13<>"",AW$4>=$J13,AW$4<=IF($K13="",TODAY(),$K13),AW$67=0),"●","") | AX13: Output: Draft plan, sections PKD_1 to PKD_6. Evidence: Draft files.
A14: 0.9 | B14: P0 | C14: Team meeting 4 (after class): review of the draft plan; decision to submit it through GitHub rather than as a PDF | D14: All | E14: 1 | F14: 1 | H14: 46303 | I14: =WORKDAY(H14,E14-1,Holidays!$A$2:$A$40) -> 46303 | J14: =IF('Project Status'!E14="","",'Project Status'!E14) -> 46303 | K14: =IF('Project Status'!F14="","",'Project Status'!F14) -> 46303 | L14: =IF('Project Status'!G14="","",'Project Status'!G14) -> Completed | M14: =IF(OR(K14="",I14=""),"",IF(K14>=I14,NETWORKDAYS(I14,K14,Holidays!$A$2:$A$40)-1,-(NETWORKDAYS(K14,I14,Holidays!$A$2:$A$40)-1))) -> 0 | N14: =IF(AND($J14<>"",N$4>=$J14,N$4<=IF($K14="",TODAY(),$K14),N$67=0),"●","") | O14: =IF(AND($J14<>"",O$4>=$J14,O$4<=IF($K14="",TODAY(),$K14),O$67=0),"●","") | P14: =IF(AND($J14<>"",P$4>=$J14,P$4<=IF($K14="",TODAY(),$K14),P$67=0),"●","") | Q14: =IF(AND($J14<>"",Q$4>=$J14,Q$4<=IF($K14="",TODAY(),$K14),Q$67=0),"●","") | R14: =IF(AND($J14<>"",R$4>=$J14,R$4<=IF($K14="",TODAY(),$K14),R$67=0),"●","") | S14: =IF(AND($J14<>"",S$4>=$J14,S$4<=IF($K14="",TODAY(),$K14),S$67=0),"●","") | T14: =IF(AND($J14<>"",T$4>=$J14,T$4<=IF($K14="",TODAY(),$K14),T$67=0),"●","") | U14: =IF(AND($J14<>"",U$4>=$J14,U$4<=IF($K14="",TODAY(),$K14),U$67=0),"●","") | ... AW14: =IF(AND($J14<>"",AW$4>=$J14,AW$4<=IF($K14="",TODAY(),$K14),AW$67=0),"●","") | AX14: Output: Agreed plan and submission format. Evidence: Reported by the team.
A15: WP1 | B15: WP1 | C15: WP1 · Project management and GitHub | E15: =NETWORKDAYS(H15,I15,Holidays!$A$2:$A$40) -> 12 | H15: =MIN(H16:H24) -> 46304 | I15: =MAX(I16:I24) -> 46322
A16: 1.1 | B16: WP1 | C16: Review and commit the introduction (PKD_1); create the folders report/, status/, gantt/, and references/ | D16: Ettore | E16: 1 | F16: 1 | H16: 46304 | I16: =WORKDAY(H16,E16-1,Holidays!$A$2:$A$40) -> 46304 | J16: =IF('Project Status'!E16="","",'Project Status'!E16) -> 46304 | K16: =IF('Project Status'!F16="","",'Project Status'!F16) -> 46304 | L16: =IF('Project Status'!G16="","",'Project Status'!G16) -> Completed | M16: =IF(OR(K16="",I16=""),"",IF(K16>=I16,NETWORKDAYS(I16,K16,Holidays!$A$2:$A$40)-1,-(NETWORKDAYS(K16,I16,Holidays!$A$2:$A$40)-1))) -> 0 | N16: =IF(AND($J16<>"",N$4>=$J16,N$4<=IF($K16="",TODAY(),$K16),N$67=0),"●","") | O16: =IF(AND($J16<>"",O$4>=$J16,O$4<=IF($K16="",TODAY(),$K16),O$67=0),"●","") | P16: =IF(AND($J16<>"",P$4>=$J16,P$4<=IF($K16="",TODAY(),$K16),P$67=0),"●","") | Q16: =IF(AND($J16<>"",Q$4>=$J16,Q$4<=IF($K16="",TODAY(),$K16),Q$67=0),"●","") | R16: =IF(AND($J16<>"",R$4>=$J16,R$4<=IF($K16="",TODAY(),$K16),R$67=0),"●","") | S16: =IF(AND($J16<>"",S$4>=$J16,S$4<=IF($K16="",TODAY(),$K16),S$67=0),"●","") | T16: =IF(AND($J16<>"",T$4>=$J16,T$4<=IF($K16="",TODAY(),$K16),T$67=0),"●","") | U16: =IF(AND($J16<>"",U$4>=$J16,U$4<=IF($K16="",TODAY(),$K16),U$67=0),"●","") | ... AW16: =IF(AND($J16<>"",AW$4>=$J16,AW$4<=IF($K16="",TODAY(),$K16),AW$67=0),"●","") | AX16: Output: Introduction and required folders in the repository. Accomplished when: The four required folders exist and the introduction is committed by its reviewer.
A17: 1.2 | B17: WP1 | C17: Review and commit the overview and team section (PKD_2); submit the repository URL on Moodle | D17: Aarón | E17: 1 | F17: 1 | G17: 1.1 | H17: 46304 | I17: =WORKDAY(H17,E17-1,Holidays!$A$2:$A$40) -> 46304 | J17: =IF('Project Status'!E17="","",'Project Status'!E17) -> 46303 | K17: =IF('Project Status'!F17="","",'Project Status'!F17) -> 46304 | L17: =IF('Project Status'!G17="","",'Project Status'!G17) -> Completed | M17: =IF(OR(K17="",I17=""),"",IF(K17>=I17,NETWORKDAYS(I17,K17,Holidays!$A$2:$A$40)-1,-(NETWORKDAYS(K17,I17,Holidays!$A$2:$A$40)-1))) -> 0 | N17: =IF(AND($J17<>"",N$4>=$J17,N$4<=IF($K17="",TODAY(),$K17),N$67=0),"●","") | O17: =IF(AND($J17<>"",O$4>=$J17,O$4<=IF($K17="",TODAY(),$K17),O$67=0),"●","") | P17: =IF(AND($J17<>"",P$4>=$J17,P$4<=IF($K17="",TODAY(),$K17),P$67=0),"●","") | Q17: =IF(AND($J17<>"",Q$4>=$J17,Q$4<=IF($K17="",TODAY(),$K17),Q$67=0),"●","") | R17: =IF(AND($J17<>"",R$4>=$J17,R$4<=IF($K17="",TODAY(),$K17),R$67=0),"●","") | S17: =IF(AND($J17<>"",S$4>=$J17,S$4<=IF($K17="",TODAY(),$K17),S$67=0),"●","") | T17: =IF(AND($J17<>"",T$4>=$J17,T$4<=IF($K17="",TODAY(),$K17),T$67=0),"●","") | U17: =IF(AND($J17<>"",U$4>=$J17,U$4<=IF($K17="",TODAY(),$K17),U$67=0),"●","") | ... AW17: =IF(AND($J17<>"",AW$4>=$J17,AW$4<=IF($K17="",TODAY(),$K17),AW$67=0),"●","") | AX17: Output: PKD_2 committed; URL submitted. Accomplished when: The URL is submitted on Moodle by 9 Oct.
A18: 1.3 | B18: WP1 | C18: Review and commit the Gantt chart (PKD_3) | D18: Bruno | E18: 1 | F18: 1 | G18: 1.1 | H18: 46304 | I18: =WORKDAY(H18,E18-1,Holidays!$A$2:$A$40) -> 46304 | J18: =IF('Project Status'!E18="","",'Project Status'!E18) -> 46303 | K18: =IF('Project Status'!F18="","",'Project Status'!F18) -> 46303 | L18: =IF('Project Status'!G18="","",'Project Status'!G18) -> Completed | M18: =IF(OR(K18="",I18=""),"",IF(K18>=I18,NETWORKDAYS(I18,K18,Holidays!$A$2:$A$40)-1,-(NETWORKDAYS(K18,I18,Holidays!$A$2:$A$40)-1))) -> -1 | N18: =IF(AND($J18<>"",N$4>=$J18,N$4<=IF($K18="",TODAY(),$K18),N$67=0),"●","") | O18: =IF(AND($J18<>"",O$4>=$J18,O$4<=IF($K18="",TODAY(),$K18),O$67=0),"●","") | P18: =IF(AND($J18<>"",P$4>=$J18,P$4<=IF($K18="",TODAY(),$K18),P$67=0),"●","") | Q18: =IF(AND($J18<>"",Q$4>=$J18,Q$4<=IF($K18="",TODAY(),$K18),Q$67=0),"●","") | R18: =IF(AND($J18<>"",R$4>=$J18,R$4<=IF($K18="",TODAY(),$K18),R$67=0),"●","") | S18: =IF(AND($J18<>"",S$4>=$J18,S$4<=IF($K18="",TODAY(),$K18),S$67=0),"●","") | T18: =IF(AND($J18<>"",T$4>=$J18,T$4<=IF($K18="",TODAY(),$K18),T$67=0),"●","") | U18: =IF(AND($J18<>"",U$4>=$J18,U$4<=IF($K18="",TODAY(),$K18),U$67=0),"●","") | ... AW18: =IF(AND($J18<>"",AW$4>=$J18,AW$4<=IF($K18="",TODAY(),$K18),AW$67=0),"●","") | AX18: Output: PKD_3 committed. Accomplished when: The chart renders on GitHub and its dates match PKD_4.
A19: 1.4 | B19: WP1 | C19: Review and commit the task details (PKD_4) | D19: Pol | E19: 1 | F19: 1 | G19: 1.1 | H19: 46304 | I19: =WORKDAY(H19,E19-1,Holidays!$A$2:$A$40) -> 46304 | J19: =IF('Project Status'!E19="","",'Project Status'!E19) -> 46303 | K19: =IF('Project Status'!F19="","",'Project Status'!F19) -> 46303 | L19: =IF('Project Status'!G19="","",'Project Status'!G19) -> Completed | M19: =IF(OR(K19="",I19=""),"",IF(K19>=I19,NETWORKDAYS(I19,K19,Holidays!$A$2:$A$40)-1,-(NETWORKDAYS(K19,I19,Holidays!$A$2:$A$40)-1))) -> -1 | N19: =IF(AND($J19<>"",N$4>=$J19,N$4<=IF($K19="",TODAY(),$K19),N$67=0),"●","") | O19: =IF(AND($J19<>"",O$4>=$J19,O$4<=IF($K19="",TODAY(),$K19),O$67=0),"●","") | P19: =IF(AND($J19<>"",P$4>=$J19,P$4<=IF($K19="",TODAY(),$K19),P$67=0),"●","") | Q19: =IF(AND($J19<>"",Q$4>=$J19,Q$4<=IF($K19="",TODAY(),$K19),Q$67=0),"●","") | R19: =IF(AND($J19<>"",R$4>=$J19,R$4<=IF($K19="",TODAY(),$K19),R$67=0),"●","") | S19: =IF(AND($J19<>"",S$4>=$J19,S$4<=IF($K19="",TODAY(),$K19),S$67=0),"●","") | T19: =IF(AND($J19<>"",T$4>=$J19,T$4<=IF($K19="",TODAY(),$K19),T$67=0),"●","") | U19: =IF(AND($J19<>"",U$4>=$J19,U$4<=IF($K19="",TODAY(),$K19),U$67=0),"●","") | ... AW19: =IF(AND($J19<>"",AW$4>=$J19,AW$4<=IF($K19="",TODAY(),$K19),AW$67=0),"●","") | AX19: Output: PKD_4 committed. Accomplished when: Every task has an owner, output, duration, predecessor, and completion criterion.
A20: 1.5 | B20: WP1 | C20: Review and commit the risk analysis and references (PKD_5, PKD_6) | D20: Leo | E20: 1 | F20: 1 | G20: 1.1 | H20: 46304 | I20: =WORKDAY(H20,E20-1,Holidays!$A$2:$A$40) -> 46304 | J20: =IF('Project Status'!E20="","",'Project Status'!E20) -> 46303 | K20: =IF('Project Status'!F20="","",'Project Status'!F20) -> 46304 | L20: =IF('Project Status'!G20="","",'Project Status'!G20) -> Completed | M20: =IF(OR(K20="",I20=""),"",IF(K20>=I20,NETWORKDAYS(I20,K20,Holidays!$A$2:$A$40)-1,-(NETWORKDAYS(K20,I20,Holidays!$A$2:$A$40)-1))) -> 0 | N20: =IF(AND($J20<>"",N$4>=$J20,N$4<=IF($K20="",TODAY(),$K20),N$67=0),"●","") | O20: =IF(AND($J20<>"",O$4>=$J20,O$4<=IF($K20="",TODAY(),$K20),O$67=0),"●","") | P20: =IF(AND($J20<>"",P$4>=$J20,P$4<=IF($K20="",TODAY(),$K20),P$67=0),"●","") | Q20: =IF(AND($J20<>"",Q$4>=$J20,Q$4<=IF($K20="",TODAY(),$K20),Q$67=0),"●","") | R20: =IF(AND($J20<>"",R$4>=$J20,R$4<=IF($K20="",TODAY(),$K20),R$67=0),"●","") | S20: =IF(AND($J20<>"",S$4>=$J20,S$4<=IF($K20="",TODAY(),$K20),S$67=0),"●","") | T20: =IF(AND($J20<>"",T$4>=$J20,T$4<=IF($K20="",TODAY(),$K20),T$67=0),"●","") | U20: =IF(AND($J20<>"",U$4>=$J20,U$4<=IF($K20="",TODAY(),$K20),U$67=0),"●","") | ... AW20: =IF(AND($J20<>"",AW$4>=$J20,AW$4<=IF($K20="",TODAY(),$K20),AW$67=0),"●","") | AX20: Output: PKD_5 and PKD_6 committed. Accomplished when: Each risk has a score and a contingency plan; every citation has a reference.
A21: 1.6 | B21: WP1 | C21: Create the Project Status document | D21: Ettore | E21: 1 | F21: 1 | G21: 1.2 | H21: 46308 | I21: =WORKDAY(H21,E21-1,Holidays!$A$2:$A$40) -> 46308 | J21: =IF('Project Status'!E21="","",'Project Status'!E21) -> 46304 | K21: =IF('Project Status'!F21="","",'Project Status'!F21) -> 46304 | L21: =IF('Project Status'!G21="","",'Project Status'!G21) -> Completed | M21: =IF(OR(K21="",I21=""),"",IF(K21>=I21,NETWORKDAYS(I21,K21,Holidays!$A$2:$A$40)-1,-(NETWORKDAYS(K21,I21,Holidays!$A$2:$A$40)-1))) -> -1 | N21: =IF(AND($J21<>"",N$4>=$J21,N$4<=IF($K21="",TODAY(),$K21),N$67=0),"●","") | O21: =IF(AND($J21<>"",O$4>=$J21,O$4<=IF($K21="",TODAY(),$K21),O$67=0),"●","") | P21: =IF(AND($J21<>"",P$4>=$J21,P$4<=IF($K21="",TODAY(),$K21),P$67=0),"●","") | Q21: =IF(AND($J21<>"",Q$4>=$J21,Q$4<=IF($K21="",TODAY(),$K21),Q$67=0),"●","") | R21: =IF(AND($J21<>"",R$4>=$J21,R$4<=IF($K21="",TODAY(),$K21),R$67=0),"●","") | S21: =IF(AND($J21<>"",S$4>=$J21,S$4<=IF($K21="",TODAY(),$K21),S$67=0),"●","") | T21: =IF(AND($J21<>"",T$4>=$J21,T$4<=IF($K21="",TODAY(),$K21),T$67=0),"●","") | U21: =IF(AND($J21<>"",U$4>=$J21,U$4<=IF($K21="",TODAY(),$K21),U$67=0),"●","") | ... AW21: =IF(AND($J21<>"",AW$4>=$J21,AW$4<=IF($K21="",TODAY(),$K21),AW$67=0),"●","") | AX21: Output: `status/` document. Accomplished when: It lists every task with owner, planned dates, real dates, status, and notes.
A22: 1.7 | B22: WP1 | C22: Weekly status update and team meeting (Fridays 16 and 23 Oct) | D22: Ettore | E22: 6 | F22: 2 | G22: 1.6 | H22: 46311 | I22: =WORKDAY(H22,E22-1,Holidays!$A$2:$A$40) -> 46318 | J22: =IF('Project Status'!E22="","",'Project Status'!E22) -> 46311 | K22: =IF('Project Status'!F22="","",'Project Status'!F22) -> 46318 | L22: =IF('Project Status'!G22="","",'Project Status'!G22) -> Completed | M22: =IF(OR(K22="",I22=""),"",IF(K22>=I22,NETWORKDAYS(I22,K22,Holidays!$A$2:$A$40)-1,-(NETWORKDAYS(K22,I22,Holidays!$A$2:$A$40)-1))) -> 0 | N22: =IF(AND($J22<>"",N$4>=$J22,N$4<=IF($K22="",TODAY(),$K22),N$67=0),"●","") | O22: =IF(AND($J22<>"",O$4>=$J22,O$4<=IF($K22="",TODAY(),$K22),O$67=0),"●","") | P22: =IF(AND($J22<>"",P$4>=$J22,P$4<=IF($K22="",TODAY(),$K22),P$67=0),"●","") | Q22: =IF(AND($J22<>"",Q$4>=$J22,Q$4<=IF($K22="",TODAY(),$K22),Q$67=0),"●","") | R22: =IF(AND($J22<>"",R$4>=$J22,R$4<=IF($K22="",TODAY(),$K22),R$67=0),"●","") | S22: =IF(AND($J22<>"",S$4>=$J22,S$4<=IF($K22="",TODAY(),$K22),S$67=0),"●","") | T22: =IF(AND($J22<>"",T$4>=$J22,T$4<=IF($K22="",TODAY(),$K22),T$67=0),"●","") | U22: =IF(AND($J22<>"",U$4>=$J22,U$4<=IF($K22="",TODAY(),$K22),U$67=0),"●","") | ... AW22: =IF(AND($J22<>"",AW$4>=$J22,AW$4<=IF($K22="",TODAY(),$K22),AW$67=0),"●","") | AX22: Output: Dated notes in `status/`. Accomplished when: After each meeting, real dates, status changes, and incidents are recorded.
A23: 1.8 | B23: WP1 | C23: Prepare the Project Status document for the 22 Oct discussion | D23: Ettore | E23: 1 | F23: 1 | G23: 1.6 | H23: 46315 | I23: =WORKDAY(H23,E23-1,Holidays!$A$2:$A$40) -> 46315 | J23: =IF('Project Status'!E23="","",'Project Status'!E23) -> 46315 | K23: =IF('Project Status'!F23="","",'Project Status'!F23) -> 46315 | L23: =IF('Project Status'!G23="","",'Project Status'!G23) -> Completed | M23: =IF(OR(K23="",I23=""),"",IF(K23>=I23,NETWORKDAYS(I23,K23,Holidays!$A$2:$A$40)-1,-(NETWORKDAYS(K23,I23,Holidays!$A$2:$A$40)-1))) -> 0 | N23: =IF(AND($J23<>"",N$4>=$J23,N$4<=IF($K23="",TODAY(),$K23),N$67=0),"●","") | O23: =IF(AND($J23<>"",O$4>=$J23,O$4<=IF($K23="",TODAY(),$K23),O$67=0),"●","") | P23: =IF(AND($J23<>"",P$4>=$J23,P$4<=IF($K23="",TODAY(),$K23),P$67=0),"●","") | Q23: =IF(AND($J23<>"",Q$4>=$J23,Q$4<=IF($K23="",TODAY(),$K23),Q$67=0),"●","") | R23: =IF(AND($J23<>"",R$4>=$J23,R$4<=IF($K23="",TODAY(),$K23),R$67=0),"●","") | S23: =IF(AND($J23<>"",S$4>=$J23,S$4<=IF($K23="",TODAY(),$K23),S$67=0),"●","") | T23: =IF(AND($J23<>"",T$4>=$J23,T$4<=IF($K23="",TODAY(),$K23),T$67=0),"●","") | U23: =IF(AND($J23<>"",U$4>=$J23,U$4<=IF($K23="",TODAY(),$K23),U$67=0),"●","") | ... AW23: =IF(AND($J23<>"",AW$4>=$J23,AW$4<=IF($K23="",TODAY(),$K23),AW$67=0),"●","") | AX23: Output: Updated `status/` document. Accomplished when: Planned and real dates, status, and notes are current on 20 Oct.
A24: 1.9 | B24: WP1 | C24: Produce the final Gantt chart with real dates (live version) | D24: Ettore | E24: 1 | F24: 1 | G24: 4.6 | H24: 46322 | I24: 46322 | J24: =IF('Project Status'!E24="","",'Project Status'!E24) -> 46321 | K24: =IF('Project Status'!F24="","",'Project Status'!F24) -> 46321 | L24: =IF('Project Status'!G24="","",'Project Status'!G24) -> Completed | M24: =IF(OR(K24="",I24=""),"",IF(K24>=I24,NETWORKDAYS(I24,K24,Holidays!$A$2:$A$40)-1,-(NETWORKDAYS(K24,I24,Holidays!$A$2:$A$40)-1))) -> -1 | N24: =IF(AND($J24<>"",N$4>=$J24,N$4<=IF($K24="",TODAY(),$K24),N$67=0),"●","") | O24: =IF(AND($J24<>"",O$4>=$J24,O$4<=IF($K24="",TODAY(),$K24),O$67=0),"●","") | P24: =IF(AND($J24<>"",P$4>=$J24,P$4<=IF($K24="",TODAY(),$K24),P$67=0),"●","") | Q24: =IF(AND($J24<>"",Q$4>=$J24,Q$4<=IF($K24="",TODAY(),$K24),Q$67=0),"●","") | R24: =IF(AND($J24<>"",R$4>=$J24,R$4<=IF($K24="",TODAY(),$K24),R$67=0),"●","") | S24: =IF(AND($J24<>"",S$4>=$J24,S$4<=IF($K24="",TODAY(),$K24),S$67=0),"●","") | T24: =IF(AND($J24<>"",T$4>=$J24,T$4<=IF($K24="",TODAY(),$K24),T$67=0),"●","") | U24: =IF(AND($J24<>"",U$4>=$J24,U$4<=IF($K24="",TODAY(),$K24),U$67=0),"●","") | ... AW24: =IF(AND($J24<>"",AW$4>=$J24,AW$4<=IF($K24="",TODAY(),$K24),AW$67=0),"●","") | AX24: Output: Final Gantt chart in `gantt/`. Accomplished when: Every task shows its real dates, and deviations are explained.
A25: WP2 | B25: WP2 | C25: WP2 · Data sources, literature, and sequences | E25: =NETWORKDAYS(H25,I25,Holidays!$A$2:$A$40) -> 5 | H25: =MIN(H26:H33) -> 46308 | I25: =MAX(I26:I33) -> 46314
A26: 2.1 | B26: WP2 | C26: Characterize the supplied sequences: translate both CDSs, compare wild type and mutant, and name the variant in HGVS nomenclature | D26: Bruno | E26: 1 | F26: 1 | G26: 1.3 | H26: 46308 | I26: 46308 | J26: =IF('Project Status'!E26="","",'Project Status'!E26) -> 46318 | K26: =IF('Project Status'!F26="","",'Project Status'!F26) -> 46319 | L26: =IF('Project Status'!G26="","",'Project Status'!G26) -> Completed | M26: =IF(OR(K26="",I26=""),"",IF(K26>=I26,NETWORKDAYS(I26,K26,Holidays!$A$2:$A$40)-1,-(NETWORKDAYS(K26,I26,Holidays!$A$2:$A$40)-1))) -> 8 | N26: =IF(AND($J26<>"",N$4>=$J26,N$4<=IF($K26="",TODAY(),$K26),N$67=0),"●","") | O26: =IF(AND($J26<>"",O$4>=$J26,O$4<=IF($K26="",TODAY(),$K26),O$67=0),"●","") | P26: =IF(AND($J26<>"",P$4>=$J26,P$4<=IF($K26="",TODAY(),$K26),P$67=0),"●","") | Q26: =IF(AND($J26<>"",Q$4>=$J26,Q$4<=IF($K26="",TODAY(),$K26),Q$67=0),"●","") | R26: =IF(AND($J26<>"",R$4>=$J26,R$4<=IF($K26="",TODAY(),$K26),R$67=0),"●","") | S26: =IF(AND($J26<>"",S$4>=$J26,S$4<=IF($K26="",TODAY(),$K26),S$67=0),"●","") | T26: =IF(AND($J26<>"",T$4>=$J26,T$4<=IF($K26="",TODAY(),$K26),T$67=0),"●","") | U26: =IF(AND($J26<>"",U$4>=$J26,U$4<=IF($K26="",TODAY(),$K26),U$67=0),"●","") | ... AW26: =IF(AND($J26<>"",AW$4>=$J26,AW$4<=IF($K26="",TODAY(),$K26),AW$67=0),"●","") | AX26: Output: Variant table (DNA and protein level). Accomplished when: Every difference is listed at DNA and protein level and verified by a second member (task 2.8).
A27: 2.2 | B27: WP2 | C27: Identify the gene, the isoform, and the reference entries (HGNC, NCBI Gene, UniProt) | D27: Leo | E27: 1 | F27: 1 | G27: 1.5 | H27: 46308 | I27: 46308 | J27: =IF('Project Status'!E27="","",'Project Status'!E27) -> 46319 | K27: =IF('Project Status'!F27="","",'Project Status'!F27) -> 46319 | L27: =IF('Project Status'!G27="","",'Project Status'!G27) -> Completed | M27: =IF(OR(K27="",I27=""),"",IF(K27>=I27,NETWORKDAYS(I27,K27,Holidays!$A$2:$A$40)-1,-(NETWORKDAYS(K27,I27,Holidays!$A$2:$A$40)-1))) -> 8 | N27: =IF(AND($J27<>"",N$4>=$J27,N$4<=IF($K27="",TODAY(),$K27),N$67=0),"●","") | O27: =IF(AND($J27<>"",O$4>=$J27,O$4<=IF($K27="",TODAY(),$K27),O$67=0),"●","") | P27: =IF(AND($J27<>"",P$4>=$J27,P$4<=IF($K27="",TODAY(),$K27),P$67=0),"●","") | Q27: =IF(AND($J27<>"",Q$4>=$J27,Q$4<=IF($K27="",TODAY(),$K27),Q$67=0),"●","") | R27: =IF(AND($J27<>"",R$4>=$J27,R$4<=IF($K27="",TODAY(),$K27),R$67=0),"●","") | S27: =IF(AND($J27<>"",S$4>=$J27,S$4<=IF($K27="",TODAY(),$K27),S$67=0),"●","") | T27: =IF(AND($J27<>"",T$4>=$J27,T$4<=IF($K27="",TODAY(),$K27),T$67=0),"●","") | U27: =IF(AND($J27<>"",U$4>=$J27,U$4<=IF($K27="",TODAY(),$K27),U$67=0),"●","") | ... AW27: =IF(AND($J27<>"",AW$4>=$J27,AW$4<=IF($K27="",TODAY(),$K27),AW$67=0),"●","") | AX27: Output: Table of identifiers. Accomplished when: The gene symbol, isoform, and accession numbers are recorded with access dates.
A28: 2.3 | B28: WP2 | C28: Collect clinical and population evidence on the variant (ClinVar, gnomAD, OMIM, literature) | D28: Leo | E28: 2 | F28: 2 | G28: 2.1, 2.5 | H28: 46310 | I28: 46311 | J28: =IF('Project Status'!E28="","",'Project Status'!E28) -> 46319 | K28: =IF('Project Status'!F28="","",'Project Status'!F28) -> 46319 | L28: =IF('Project Status'!G28="","",'Project Status'!G28) -> Completed | M28: =IF(OR(K28="",I28=""),"",IF(K28>=I28,NETWORKDAYS(I28,K28,Holidays!$A$2:$A$40)-1,-(NETWORKDAYS(K28,I28,Holidays!$A$2:$A$40)-1))) -> 5 | N28: =IF(AND($J28<>"",N$4>=$J28,N$4<=IF($K28="",TODAY(),$K28),N$67=0),"●","") | O28: =IF(AND($J28<>"",O$4>=$J28,O$4<=IF($K28="",TODAY(),$K28),O$67=0),"●","") | P28: =IF(AND($J28<>"",P$4>=$J28,P$4<=IF($K28="",TODAY(),$K28),P$67=0),"●","") | Q28: =IF(AND($J28<>"",Q$4>=$J28,Q$4<=IF($K28="",TODAY(),$K28),Q$67=0),"●","") | R28: =IF(AND($J28<>"",R$4>=$J28,R$4<=IF($K28="",TODAY(),$K28),R$67=0),"●","") | S28: =IF(AND($J28<>"",S$4>=$J28,S$4<=IF($K28="",TODAY(),$K28),S$67=0),"●","") | T28: =IF(AND($J28<>"",T$4>=$J28,T$4<=IF($K28="",TODAY(),$K28),T$67=0),"●","") | U28: =IF(AND($J28<>"",U$4>=$J28,U$4<=IF($K28="",TODAY(),$K28),U$67=0),"●","") | ... AW28: =IF(AND($J28<>"",AW$4>=$J28,AW$4<=IF($K28="",TODAY(),$K28),AW$67=0),"●","") | AX28: Output: Evidence table with sources. Accomplished when: Classification, allele frequency, and published functional data are recorded with sources.
A29: 2.4 | B29: WP2 | C29: Review the literature on PK and PKD: normal function, mechanism, inheritance, and clinical features | D29: Aarón | E29: 3 | F29: 3 | G29: 1.2 | H29: 46308 | I29: 46310 | J29: =IF('Project Status'!E29="","",'Project Status'!E29) -> 46318 | K29: =IF('Project Status'!F29="","",'Project Status'!F29) -> 46321 | L29: =IF('Project Status'!G29="","",'Project Status'!G29) -> Completed | M29: =IF(OR(K29="",I29=""),"",IF(K29>=I29,NETWORKDAYS(I29,K29,Holidays!$A$2:$A$40)-1,-(NETWORKDAYS(K29,I29,Holidays!$A$2:$A$40)-1))) -> 7 | N29: =IF(AND($J29<>"",N$4>=$J29,N$4<=IF($K29="",TODAY(),$K29),N$67=0),"●","") | O29: =IF(AND($J29<>"",O$4>=$J29,O$4<=IF($K29="",TODAY(),$K29),O$67=0),"●","") | P29: =IF(AND($J29<>"",P$4>=$J29,P$4<=IF($K29="",TODAY(),$K29),P$67=0),"●","") | Q29: =IF(AND($J29<>"",Q$4>=$J29,Q$4<=IF($K29="",TODAY(),$K29),Q$67=0),"●","") | R29: =IF(AND($J29<>"",R$4>=$J29,R$4<=IF($K29="",TODAY(),$K29),R$67=0),"●","") | S29: =IF(AND($J29<>"",S$4>=$J29,S$4<=IF($K29="",TODAY(),$K29),S$67=0),"●","") | T29: =IF(AND($J29<>"",T$4>=$J29,T$4<=IF($K29="",TODAY(),$K29),T$67=0),"●","") | U29: =IF(AND($J29<>"",U$4>=$J29,U$4<=IF($K29="",TODAY(),$K29),U$67=0),"●","") | ... AW29: =IF(AND($J29<>"",AW$4>=$J29,AW$4<=IF($K29="",TODAY(),$K29),AW$67=0),"●","") | AX29: Output: Annotated literature notes. Accomplished when: Each statement planned for the Background has at least one primary or review source.
A30: 2.5 | B30: WP2 | C30: Retrieve the reviewed orthologous sequences: rat, mouse, and dog (outgroup) | D30: Leo | E30: 1 | F30: 1 | G30: 2.2 | H30: 46309 | I30: 46309 | J30: =IF('Project Status'!E30="","",'Project Status'!E30) -> 46319 | K30: =IF('Project Status'!F30="","",'Project Status'!F30) -> 46319 | L30: =IF('Project Status'!G30="","",'Project Status'!G30) -> Completed | M30: =IF(OR(K30="",I30=""),"",IF(K30>=I30,NETWORKDAYS(I30,K30,Holidays!$A$2:$A$40)-1,-(NETWORKDAYS(K30,I30,Holidays!$A$2:$A$40)-1))) -> 7 | N30: =IF(AND($J30<>"",N$4>=$J30,N$4<=IF($K30="",TODAY(),$K30),N$67=0),"●","") | O30: =IF(AND($J30<>"",O$4>=$J30,O$4<=IF($K30="",TODAY(),$K30),O$67=0),"●","") | P30: =IF(AND($J30<>"",P$4>=$J30,P$4<=IF($K30="",TODAY(),$K30),P$67=0),"●","") | Q30: =IF(AND($J30<>"",Q$4>=$J30,Q$4<=IF($K30="",TODAY(),$K30),Q$67=0),"●","") | R30: =IF(AND($J30<>"",R$4>=$J30,R$4<=IF($K30="",TODAY(),$K30),R$67=0),"●","") | S30: =IF(AND($J30<>"",S$4>=$J30,S$4<=IF($K30="",TODAY(),$K30),S$67=0),"●","") | T30: =IF(AND($J30<>"",T$4>=$J30,T$4<=IF($K30="",TODAY(),$K30),T$67=0),"●","") | U30: =IF(AND($J30<>"",U$4>=$J30,U$4<=IF($K30="",TODAY(),$K30),U$67=0),"●","") | ... AW30: =IF(AND($J30<>"",AW$4>=$J30,AW$4<=IF($K30="",TODAY(),$K30),AW$67=0),"●","") | AX30: Output: FASTA files and accession list. Accomplished when: Every sequence is saved in the repository with its accession number.
A31: 2.6 | B31: WP2 | C31: Select the experimental structures: wild-type and mutant human R-type PK; rat PK | D31: Pol | E31: 1 | F31: 1 | G31: 1.4 | H31: 46308 | I31: 46308 | J31: =IF('Project Status'!E31="","",'Project Status'!E31) -> 46319 | K31: =IF('Project Status'!F31="","",'Project Status'!F31) -> 46321 | L31: =IF('Project Status'!G31="","",'Project Status'!G31) -> Completed | M31: =IF(OR(K31="",I31=""),"",IF(K31>=I31,NETWORKDAYS(I31,K31,Holidays!$A$2:$A$40)-1,-(NETWORKDAYS(K31,I31,Holidays!$A$2:$A$40)-1))) -> 9 | N31: =IF(AND($J31<>"",N$4>=$J31,N$4<=IF($K31="",TODAY(),$K31),N$67=0),"●","") | O31: =IF(AND($J31<>"",O$4>=$J31,O$4<=IF($K31="",TODAY(),$K31),O$67=0),"●","") | P31: =IF(AND($J31<>"",P$4>=$J31,P$4<=IF($K31="",TODAY(),$K31),P$67=0),"●","") | Q31: =IF(AND($J31<>"",Q$4>=$J31,Q$4<=IF($K31="",TODAY(),$K31),Q$67=0),"●","") | R31: =IF(AND($J31<>"",R$4>=$J31,R$4<=IF($K31="",TODAY(),$K31),R$67=0),"●","") | S31: =IF(AND($J31<>"",S$4>=$J31,S$4<=IF($K31="",TODAY(),$K31),S$67=0),"●","") | T31: =IF(AND($J31<>"",T$4>=$J31,T$4<=IF($K31="",TODAY(),$K31),T$67=0),"●","") | U31: =IF(AND($J31<>"",U$4>=$J31,U$4<=IF($K31="",TODAY(),$K31),U$67=0),"●","") | ... AW31: =IF(AND($J31<>"",AW$4>=$J31,AW$4<=IF($K31="",TODAY(),$K31),AW$67=0),"●","") | AX31: Output: Table of PDB entries (method, resolution, construct). Accomplished when: One wild-type and one mutant entry are chosen, with the reasons recorded.
A32: 2.7 | B32: WP2 | C32: Archive the sources in references/ and maintain the reference list | D32: Leo | E32: 1 | F32: 1 | G32: 2.3, 2.4 | H32: 46314 | I32: 46314 | J32: =IF('Project Status'!E32="","",'Project Status'!E32) -> 46319 | K32: =IF('Project Status'!F32="","",'Project Status'!F32) -> 46321 | L32: =IF('Project Status'!G32="","",'Project Status'!G32) -> Completed | M32: =IF(OR(K32="",I32=""),"",IF(K32>=I32,NETWORKDAYS(I32,K32,Holidays!$A$2:$A$40)-1,-(NETWORKDAYS(K32,I32,Holidays!$A$2:$A$40)-1))) -> 5 | N32: =IF(AND($J32<>"",N$4>=$J32,N$4<=IF($K32="",TODAY(),$K32),N$67=0),"●","") | O32: =IF(AND($J32<>"",O$4>=$J32,O$4<=IF($K32="",TODAY(),$K32),O$67=0),"●","") | P32: =IF(AND($J32<>"",P$4>=$J32,P$4<=IF($K32="",TODAY(),$K32),P$67=0),"●","") | Q32: =IF(AND($J32<>"",Q$4>=$J32,Q$4<=IF($K32="",TODAY(),$K32),Q$67=0),"●","") | R32: =IF(AND($J32<>"",R$4>=$J32,R$4<=IF($K32="",TODAY(),$K32),R$67=0),"●","") | S32: =IF(AND($J32<>"",S$4>=$J32,S$4<=IF($K32="",TODAY(),$K32),S$67=0),"●","") | T32: =IF(AND($J32<>"",T$4>=$J32,T$4<=IF($K32="",TODAY(),$K32),T$67=0),"●","") | U32: =IF(AND($J32<>"",U$4>=$J32,U$4<=IF($K32="",TODAY(),$K32),U$67=0),"●","") | ... AW32: =IF(AND($J32<>"",AW$4>=$J32,AW$4<=IF($K32="",TODAY(),$K32),AW$67=0),"●","") | AX32: Output: PDFs and Mini Oxford reference list. Accomplished when: Every cited source is archived and listed in the required style.
A33: 2.8 | B33: WP2 | C33: Verify the sequence characterization independently: repeat the translation and the comparison of the four files | D33: Ettore | E33: 1 | F33: 1 | G33: 2.1 | H33: 46309 | I33: 46309 | J33: =IF('Project Status'!E33="","",'Project Status'!E33) -> 46319 | K33: =IF('Project Status'!F33="","",'Project Status'!F33) -> 46319 | L33: =IF('Project Status'!G33="","",'Project Status'!G33) -> Completed | M33: =IF(OR(K33="",I33=""),"",IF(K33>=I33,NETWORKDAYS(I33,K33,Holidays!$A$2:$A$40)-1,-(NETWORKDAYS(K33,I33,Holidays!$A$2:$A$40)-1))) -> 7 | N33: =IF(AND($J33<>"",N$4>=$J33,N$4<=IF($K33="",TODAY(),$K33),N$67=0),"●","") | O33: =IF(AND($J33<>"",O$4>=$J33,O$4<=IF($K33="",TODAY(),$K33),O$67=0),"●","") | P33: =IF(AND($J33<>"",P$4>=$J33,P$4<=IF($K33="",TODAY(),$K33),P$67=0),"●","") | Q33: =IF(AND($J33<>"",Q$4>=$J33,Q$4<=IF($K33="",TODAY(),$K33),Q$67=0),"●","") | R33: =IF(AND($J33<>"",R$4>=$J33,R$4<=IF($K33="",TODAY(),$K33),R$67=0),"●","") | S33: =IF(AND($J33<>"",S$4>=$J33,S$4<=IF($K33="",TODAY(),$K33),S$67=0),"●","") | T33: =IF(AND($J33<>"",T$4>=$J33,T$4<=IF($K33="",TODAY(),$K33),T$67=0),"●","") | U33: =IF(AND($J33<>"",U$4>=$J33,U$4<=IF($K33="",TODAY(),$K33),U$67=0),"●","") | ... AW33: =IF(AND($J33<>"",AW$4>=$J33,AW$4<=IF($K33="",TODAY(),$K33),AW$67=0),"●","") | AX33: Output: Verification note. Accomplished when: The variant table of task 2.1 is confirmed, or each discrepancy is resolved with its owner.
A34: WP3 | B34: WP3 | C34: WP3 · Sequence and structure analysis | E34: =NETWORKDAYS(H34,I34,Holidays!$A$2:$A$40) -> 9 | H34: =MIN(H35:H45) -> 46309 | I34: =MAX(I35:I45) -> 46321
A35: 3.1 | B35: WP3 | C35: Pairwise alignments of human PK with the rat and mouse orthologs (protein and CDS) | D35: Bruno | E35: 1 | F35: 1 | G35: 2.1, 2.5 | H35: 46310 | I35: 46310 | J35: =IF('Project Status'!E35="","",'Project Status'!E35) -> 46318 | K35: =IF('Project Status'!F35="","",'Project Status'!F35) -> 46319 | L35: =IF('Project Status'!G35="","",'Project Status'!G35) -> Completed | M35: =IF(OR(K35="",I35=""),"",IF(K35>=I35,NETWORKDAYS(I35,K35,Holidays!$A$2:$A$40)-1,-(NETWORKDAYS(K35,I35,Holidays!$A$2:$A$40)-1))) -> 6 | N35: =IF(AND($J35<>"",N$4>=$J35,N$4<=IF($K35="",TODAY(),$K35),N$67=0),"●","") | O35: =IF(AND($J35<>"",O$4>=$J35,O$4<=IF($K35="",TODAY(),$K35),O$67=0),"●","") | P35: =IF(AND($J35<>"",P$4>=$J35,P$4<=IF($K35="",TODAY(),$K35),P$67=0),"●","") | Q35: =IF(AND($J35<>"",Q$4>=$J35,Q$4<=IF($K35="",TODAY(),$K35),Q$67=0),"●","") | R35: =IF(AND($J35<>"",R$4>=$J35,R$4<=IF($K35="",TODAY(),$K35),R$67=0),"●","") | S35: =IF(AND($J35<>"",S$4>=$J35,S$4<=IF($K35="",TODAY(),$K35),S$67=0),"●","") | T35: =IF(AND($J35<>"",T$4>=$J35,T$4<=IF($K35="",TODAY(),$K35),T$67=0),"●","") | U35: =IF(AND($J35<>"",U$4>=$J35,U$4<=IF($K35="",TODAY(),$K35),U$67=0),"●","") | ... AW35: =IF(AND($J35<>"",AW$4>=$J35,AW$4<=IF($K35="",TODAY(),$K35),AW$67=0),"●","") | AX35: Output: Alignments and identity table. Accomplished when: Percent identity and similarity are reported for each pair, with tool and parameters.
A36: 3.2 | B36: WP3 | C36: Multiple sequence alignment of human, rat, mouse, and dog PK; conservation of the substituted position and lineage of each difference | D36: Bruno | E36: 2 | F36: 2 | G36: 3.1 | H36: 46311 | I36: 46314 | J36: =IF('Project Status'!E36="","",'Project Status'!E36) -> 46319 | K36: =IF('Project Status'!F36="","",'Project Status'!F36) -> 46319 | L36: =IF('Project Status'!G36="","",'Project Status'!G36) -> Completed | M36: =IF(OR(K36="",I36=""),"",IF(K36>=I36,NETWORKDAYS(I36,K36,Holidays!$A$2:$A$40)-1,-(NETWORKDAYS(K36,I36,Holidays!$A$2:$A$40)-1))) -> 4 | N36: =IF(AND($J36<>"",N$4>=$J36,N$4<=IF($K36="",TODAY(),$K36),N$67=0),"●","") | O36: =IF(AND($J36<>"",O$4>=$J36,O$4<=IF($K36="",TODAY(),$K36),O$67=0),"●","") | P36: =IF(AND($J36<>"",P$4>=$J36,P$4<=IF($K36="",TODAY(),$K36),P$67=0),"●","") | Q36: =IF(AND($J36<>"",Q$4>=$J36,Q$4<=IF($K36="",TODAY(),$K36),Q$67=0),"●","") | R36: =IF(AND($J36<>"",R$4>=$J36,R$4<=IF($K36="",TODAY(),$K36),R$67=0),"●","") | S36: =IF(AND($J36<>"",S$4>=$J36,S$4<=IF($K36="",TODAY(),$K36),S$67=0),"●","") | T36: =IF(AND($J36<>"",T$4>=$J36,T$4<=IF($K36="",TODAY(),$K36),T$67=0),"●","") | U36: =IF(AND($J36<>"",U$4>=$J36,U$4<=IF($K36="",TODAY(),$K36),U$67=0),"●","") | ... AW36: =IF(AND($J36<>"",AW$4>=$J36,AW$4<=IF($K36="",TODAY(),$K36),AW$67=0),"●","") | AX36: Output: Alignment figure and conservation notes. Accomplished when: The residue at the substituted position is reported for every species, and the lineage of each change is stated.
A37: 3.3 | B37: WP3 | C37: Map the substituted residue on the wild-type structure: distances to the active site, the allosteric site, and the domain and subunit interfaces | D37: Pol | E37: 2 | F37: 2 | G37: 2.1, 2.6 | H37: 46309 | I37: 46310 | J37: =IF('Project Status'!E37="","",'Project Status'!E37) -> 46319 | K37: =IF('Project Status'!F37="","",'Project Status'!F37) -> 46319 | L37: =IF('Project Status'!G37="","",'Project Status'!G37) -> Completed | M37: =IF(OR(K37="",I37=""),"",IF(K37>=I37,NETWORKDAYS(I37,K37,Holidays!$A$2:$A$40)-1,-(NETWORKDAYS(K37,I37,Holidays!$A$2:$A$40)-1))) -> 6 | N37: =IF(AND($J37<>"",N$4>=$J37,N$4<=IF($K37="",TODAY(),$K37),N$67=0),"●","") | O37: =IF(AND($J37<>"",O$4>=$J37,O$4<=IF($K37="",TODAY(),$K37),O$67=0),"●","") | P37: =IF(AND($J37<>"",P$4>=$J37,P$4<=IF($K37="",TODAY(),$K37),P$67=0),"●","") | Q37: =IF(AND($J37<>"",Q$4>=$J37,Q$4<=IF($K37="",TODAY(),$K37),Q$67=0),"●","") | R37: =IF(AND($J37<>"",R$4>=$J37,R$4<=IF($K37="",TODAY(),$K37),R$67=0),"●","") | S37: =IF(AND($J37<>"",S$4>=$J37,S$4<=IF($K37="",TODAY(),$K37),S$67=0),"●","") | T37: =IF(AND($J37<>"",T$4>=$J37,T$4<=IF($K37="",TODAY(),$K37),T$67=0),"●","") | U37: =IF(AND($J37<>"",U$4>=$J37,U$4<=IF($K37="",TODAY(),$K37),U$67=0),"●","") | ... AW37: =IF(AND($J37<>"",AW$4>=$J37,AW$4<=IF($K37="",TODAY(),$K37),AW$67=0),"●","") | AX37: Output: Annotated structure figure and distance table. Accomplished when: Distances are measured in a stated structure and chain.
A38: 3.4 | B38: WP3 | C38: Superpose the wild-type and mutant structures (repeated in the 22 Oct lab) | D38: Pol | E38: 2 | F38: 2 | G38: 3.3 | H38: 46311 | I38: 46314 | J38: =IF('Project Status'!E38="","",'Project Status'!E38) -> 46319 | K38: =IF('Project Status'!F38="","",'Project Status'!F38) -> 46319 | L38: =IF('Project Status'!G38="","",'Project Status'!G38) -> Completed | M38: =IF(OR(K38="",I38=""),"",IF(K38>=I38,NETWORKDAYS(I38,K38,Holidays!$A$2:$A$40)-1,-(NETWORKDAYS(K38,I38,Holidays!$A$2:$A$40)-1))) -> 4 | N38: =IF(AND($J38<>"",N$4>=$J38,N$4<=IF($K38="",TODAY(),$K38),N$67=0),"●","") | O38: =IF(AND($J38<>"",O$4>=$J38,O$4<=IF($K38="",TODAY(),$K38),O$67=0),"●","") | P38: =IF(AND($J38<>"",P$4>=$J38,P$4<=IF($K38="",TODAY(),$K38),P$67=0),"●","") | Q38: =IF(AND($J38<>"",Q$4>=$J38,Q$4<=IF($K38="",TODAY(),$K38),Q$67=0),"●","") | R38: =IF(AND($J38<>"",R$4>=$J38,R$4<=IF($K38="",TODAY(),$K38),R$67=0),"●","") | S38: =IF(AND($J38<>"",S$4>=$J38,S$4<=IF($K38="",TODAY(),$K38),S$67=0),"●","") | T38: =IF(AND($J38<>"",T$4>=$J38,T$4<=IF($K38="",TODAY(),$K38),T$67=0),"●","") | U38: =IF(AND($J38<>"",U$4>=$J38,U$4<=IF($K38="",TODAY(),$K38),U$67=0),"●","") | ... AW38: =IF(AND($J38<>"",AW$4>=$J38,AW$4<=IF($K38="",TODAY(),$K38),AW$67=0),"●","") | AX38: Output: Superposition figure and RMSD values. Accomplished when: Global and local differences are quantified with the method stated.
A39: 3.5 | B39: WP3 | C39: Compare the human R-type and rat L-type structures around the substituted position | D39: Pol | E39: 1 | F39: 1 | G39: 3.4, 3.2 | H39: 46315 | I39: 46315 | J39: =IF('Project Status'!E39="","",'Project Status'!E39) -> 46319 | K39: =IF('Project Status'!F39="","",'Project Status'!F39) | L39: =IF('Project Status'!G39="","",'Project Status'!G39) -> Canceled | M39: =IF(OR(K39="",I39=""),"",IF(K39>=I39,NETWORKDAYS(I39,K39,Holidays!$A$2:$A$40)-1,-(NETWORKDAYS(K39,I39,Holidays!$A$2:$A$40)-1))) | N39: =IF(AND($J39<>"",N$4>=$J39,N$4<=IF($K39="",TODAY(),$K39),N$67=0),"●","") | O39: =IF(AND($J39<>"",O$4>=$J39,O$4<=IF($K39="",TODAY(),$K39),O$67=0),"●","") | P39: =IF(AND($J39<>"",P$4>=$J39,P$4<=IF($K39="",TODAY(),$K39),P$67=0),"●","") | Q39: =IF(AND($J39<>"",Q$4>=$J39,Q$4<=IF($K39="",TODAY(),$K39),Q$67=0),"●","") | R39: =IF(AND($J39<>"",R$4>=$J39,R$4<=IF($K39="",TODAY(),$K39),R$67=0),"●","") | S39: =IF(AND($J39<>"",S$4>=$J39,S$4<=IF($K39="",TODAY(),$K39),S$67=0),"●","") | T39: =IF(AND($J39<>"",T$4>=$J39,T$4<=IF($K39="",TODAY(),$K39),T$67=0),"●","") | U39: =IF(AND($J39<>"",U$4>=$J39,U$4<=IF($K39="",TODAY(),$K39),U$67=0),"●","") | ... AW39: =IF(AND($J39<>"",AW$4>=$J39,AW$4<=IF($K39="",TODAY(),$K39),AW$67=0),"●","") | AX39: Output: Comparison figure and notes. Accomplished when: The local environment of the position is described in both species.
A40: 3.6 | B40: WP3 | C40: Assess pathogenicity: combine clinical, population, conservation, structural, and biochemical evidence | D40: Aarón | E40: 1 | F40: 1 | G40: 2.3, 2.4, 3.1 | H40: 46314 | I40: 46314 | J40: =IF('Project Status'!E40="","",'Project Status'!E40) -> 46321 | K40: =IF('Project Status'!F40="","",'Project Status'!F40) -> 46321 | L40: =IF('Project Status'!G40="","",'Project Status'!G40) -> Completed | M40: =IF(OR(K40="",I40=""),"",IF(K40>=I40,NETWORKDAYS(I40,K40,Holidays!$A$2:$A$40)-1,-(NETWORKDAYS(K40,I40,Holidays!$A$2:$A$40)-1))) -> 5 | N40: =IF(AND($J40<>"",N$4>=$J40,N$4<=IF($K40="",TODAY(),$K40),N$67=0),"●","") | O40: =IF(AND($J40<>"",O$4>=$J40,O$4<=IF($K40="",TODAY(),$K40),O$67=0),"●","") | P40: =IF(AND($J40<>"",P$4>=$J40,P$4<=IF($K40="",TODAY(),$K40),P$67=0),"●","") | Q40: =IF(AND($J40<>"",Q$4>=$J40,Q$4<=IF($K40="",TODAY(),$K40),Q$67=0),"●","") | R40: =IF(AND($J40<>"",R$4>=$J40,R$4<=IF($K40="",TODAY(),$K40),R$67=0),"●","") | S40: =IF(AND($J40<>"",S$4>=$J40,S$4<=IF($K40="",TODAY(),$K40),S$67=0),"●","") | T40: =IF(AND($J40<>"",T$4>=$J40,T$4<=IF($K40="",TODAY(),$K40),T$67=0),"●","") | U40: =IF(AND($J40<>"",U$4>=$J40,U$4<=IF($K40="",TODAY(),$K40),U$67=0),"●","") | ... AW40: =IF(AND($J40<>"",AW$4>=$J40,AW$4<=IF($K40="",TODAY(),$K40),AW$67=0),"●","") | AX40: Output: Evidence summary table. Accomplished when: Each line of evidence is classified as measured result, hypothesis, or open question.
...

Sheet Members
A1: Members, roles, and distribution of the planned work (formulas read the Tasks sheet; Phase 0 excluded)
A3: Owner | B3: Full name | C3: Role | D3: Tasks owned | E3: Effort (working days) | F3: Completed | G3: In progress | H3: Incidents | I3: GitHub username
A4: Aarón | B4: Aarón Godino Martínez | C4: Product Owner | D4: =COUNTIFS(Tasks!$D$5:$D$62,A4,Tasks!$B$5:$B$62,"<>P0",Tasks!$A$5:$A$62,"<>WP*") -> 8 | E4: =SUMIFS(Tasks!$F$5:$F$62,Tasks!$D$5:$D$62,A4,Tasks!$B$5:$B$62,"<>P0") -> 11 | F4: =COUNTIFS(Tasks!$D$5:$D$62,A4,Tasks!$L$5:$L$62,"Completed",Tasks!$B$5:$B$62,"<>P0") -> 7 | G4: =COUNTIFS(Tasks!$D$5:$D$62,A4,Tasks!$L$5:$L$62,"In progress") -> 0 | H4: =COUNTIFS(Tasks!$D$5:$D$62,A4,Tasks!$L$5:$L$62,"Incident") -> 0 | I4: Idonthaveanyideafornames
A5: Bruno | B5: Bruno Carrasquilla | C5: Sequence Analyst | D5: =COUNTIFS(Tasks!$D$5:$D$62,A5,Tasks!$B$5:$B$62,"<>P0",Tasks!$A$5:$A$62,"<>WP*") -> 8 | E5: =SUMIFS(Tasks!$F$5:$F$62,Tasks!$D$5:$D$62,A5,Tasks!$B$5:$B$62,"<>P0") -> 11 | F5: =COUNTIFS(Tasks!$D$5:$D$62,A5,Tasks!$L$5:$L$62,"Completed",Tasks!$B$5:$B$62,"<>P0") -> 6 | G5: =COUNTIFS(Tasks!$D$5:$D$62,A5,Tasks!$L$5:$L$62,"In progress") -> 0 | H5: =COUNTIFS(Tasks!$D$5:$D$62,A5,Tasks!$L$5:$L$62,"Incident") -> 0 | I5: BrunoCarrasquilla
A6: Ettore | B6: Ettore Colombo | C6: Project Manager | D6: =COUNTIFS(Tasks!$D$5:$D$62,A6,Tasks!$B$5:$B$62,"<>P0",Tasks!$A$5:$A$62,"<>WP*") -> 9 | E6: =SUMIFS(Tasks!$F$5:$F$62,Tasks!$D$5:$D$62,A6,Tasks!$B$5:$B$62,"<>P0") -> 11 | F6: =COUNTIFS(Tasks!$D$5:$D$62,A6,Tasks!$L$5:$L$62,"Completed",Tasks!$B$5:$B$62,"<>P0") -> 8 | G6: =COUNTIFS(Tasks!$D$5:$D$62,A6,Tasks!$L$5:$L$62,"In progress") -> 0 | H6: =COUNTIFS(Tasks!$D$5:$D$62,A6,Tasks!$L$5:$L$62,"Incident") -> 0 | I6: AIHector
A7: Leo | B7: Leo Nader Al Hourani | C7: Data and GitHub Manager | D7: =COUNTIFS(Tasks!$D$5:$D$62,A7,Tasks!$B$5:$B$62,"<>P0",Tasks!$A$5:$A$62,"<>WP*") -> 10 | E7: =SUMIFS(Tasks!$F$5:$F$62,Tasks!$D$5:$D$62,A7,Tasks!$B$5:$B$62,"<>P0") -> 12 | F7: =COUNTIFS(Tasks!$D$5:$D$62,A7,Tasks!$L$5:$L$62,"Completed",Tasks!$B$5:$B$62,"<>P0") -> 8 | G7: =COUNTIFS(Tasks!$D$5:$D$62,A7,Tasks!$L$5:$L$62,"In progress") -> 0 | H7: =COUNTIFS(Tasks!$D$5:$D$62,A7,Tasks!$L$5:$L$62,"Incident") -> 0 | I7: XxNaderTheKing08Xx
A8: Pol | B8: Pol Monllau | C8: Structure Analyst | D8: =COUNTIFS(Tasks!$D$5:$D$62,A8,Tasks!$B$5:$B$62,"<>P0",Tasks!$A$5:$A$62,"<>WP*") -> 8 | E8: =SUMIFS(Tasks!$F$5:$F$62,Tasks!$D$5:$D$62,A8,Tasks!$B$5:$B$62,"<>P0") -> 11 | F8: =COUNTIFS(Tasks!$D$5:$D$62,A8,Tasks!$L$5:$L$62,"Completed",Tasks!$B$5:$B$62,"<>P0") -> 6 | G8: =COUNTIFS(Tasks!$D$5:$D$62,A8,Tasks!$L$5:$L$62,"In progress") -> 0 | H8: =COUNTIFS(Tasks!$D$5:$D$62,A8,Tasks!$L$5:$L$62,"Incident") -> 0 | I8: polmonllau
A9: Total | D9: =SUM(D4:D8) -> 43 | E9: =SUM(E4:E8) -> 56 | F9: =SUM(F4:F8) -> 35 | G9: =SUM(G4:G8) -> 0 | H9: =SUM(H4:H8) -> 0

Sheet Milestones
A1: ID | B1: Milestone | C1: Planned date | D1: Real date | E1: Status | F1: Source | G1: Delay (working days)
A2: M0 | B2: Project presented; repository created | C2: 46282 | D2: 46282 | E2: Completed | F2: Overview; commits | G2: =IF(D2="","",IF(D2>=C2,NETWORKDAYS(C2,D2,Holidays!$A$2:$A$40)-1,-(NETWORKDAYS(D2,C2,Holidays!$A$2:$A$40)-1))) -> 0
